Workbook

Sheet Cover

Sheet Drivers
B2: Drivers & Assumptions
D4: 2023 | E4: =D4+1 -> 2024 | F4: =E4+1 -> 2025 | G4: =F4+1 -> 2026 | H4: =G4+1 -> 2027 | I4: =H4+1 -> 2028 | J4: =I4+1 -> 2029
C5: ($ in millions) | D5: ="FY"&D4&"A" -> FY2023A | E5: ="FY"&E4&"A" -> FY2024A | F5: ="FY"&F4&"E" -> FY2025E | G5: ="FY"&G4&"E" -> FY2026E | H5: ="FY"&H4&"E" -> FY2027E | I5: ="FY"&I4&"E" -> FY2028E | J5: ="FY"&J4&"E" -> FY2029E
B7: Revenue growth (%) | D7: n/a | E7: n/a | F7: 0.1 | G7: 0.09 | H7: 0.08 | I7: 0.07 | J7: 0.06
B8: Cost of revenue (% rev) | F8: 0.165 | G8: 0.163 | H8: 0.162 | I8: 0.16 | J8: 0.16
B9: Operations & support (% rev) | F9: 0.115 | G9: 0.113 | H9: 0.112 | I9: 0.11 | J9: 0.11
B10: Product development (% rev) | F10: 0.18 | G10: 0.175 | H10: 0.172 | I10: 0.17 | J10: 0.168
B11: Sales & marketing (% rev) | F11: 0.19 | G11: 0.188 | H11: 0.185 | I11: 0.183 | J11: 0.18
B12: General & admin (% rev) | F12: 0.105 | G12: 0.103 | H12: 0.102 | I12: 0.1 | J12: 0.1
B14: Tax rate (%) | F14: 0.22 | G14: 0.22 | H14: 0.22 | I14: 0.22 | J14: 0.22
B15: Interest yield on opening cash+ST inv (%) | F15: 0.04 | G15: 0.04 | H15: 0.038 | I15: 0.038 | J15: 0.038
B16: Other income/(expense), net ($mm) | F16: -40 | G16: -40 | H16: -40 | I16: -40 | J16: -40
B18: D&A (% rev) [asset-light] | F18: 0.005 | G18: 0.005 | H18: 0.005 | I18: 0.005 | J18: 0.005
B19: Capex (% rev) [asset-light] | F19: 0.004 | G19: 0.004 | H19: 0.004 | I19: 0.004 | J19: 0.004
B20: Stock-based comp (% rev) | F20: 0.12 | G20: 0.115 | H20: 0.11 | I20: 0.105 | J20: 0.1
B22: Working capital (% of revenue)
B23: Prepaids & other assets | F23: 0.057 | G23: 0.057 | H23: 0.057 | I23: 0.057 | J23: 0.057
B24: Accrued exp & other liabilities | F24: 0.235 | G24: 0.235 | H24: 0.235 | I24: 0.235 | J24: 0.235
B25: Unearned fees (deferred rev) | F25: 0.145 | G25: 0.145 | H25: 0.145 | I25: 0.145 | J25: 0.145
B27: DCF inputs
B28: Risk-free rate | D28: 0.043
B29: Equity risk premium | D29: 0.05
B30: Beta | D30: 1.25
B31: Pre-tax cost of debt | D31: 0.05
B32: Terminal growth rate | D32: 0.03
B33: Current share price ($) | D33: 126
B34: Diluted shares outstanding (mm) | D34: 635

Sheet Income Statement
B2: Income Statement
D4: 2023 | E4: =D4+1 -> 2024 | F4: =E4+1 -> 2025 | G4: =F4+1 -> 2026 | H4: =G4+1 -> 2027 | I4: =H4+1 -> 2028 | J4: =I4+1 -> 2029
C5: ($ in millions) | D5: ="FY"&D4&"A" -> FY2023A | E5: ="FY"&E4&"A" -> FY2024A | F5: ="FY"&F4&"E" -> FY2025E | G5: ="FY"&G4&"E" -> FY2026E | H5: ="FY"&H4&"E" -> FY2027E | I5: ="FY"&I4&"E" -> FY2028E | J5: ="FY"&J4&"E" -> FY2029E
B7: Revenue | D7: 9917 | E7: 11102 | F7: =E7*(1+Drivers!F7) -> 12212.2 | G7: =F7*(1+Drivers!G7) -> 13311.298 | H7: =G7*(1+Drivers!H7) -> 14376.202 | I7: =H7*(1+Drivers!I7) -> 15382.536 | J7: =I7*(1+Drivers!J7) -> 16305.488
B8: Cost of revenue | D8: 1703 | E8: 1878 | F8: =F7*Drivers!F8 -> 2015.013 | G8: =G7*Drivers!G8 -> 2169.7416 | H8: =H7*Drivers!H8 -> 2328.9447 | I8: =I7*Drivers!I8 -> 2461.2058 | J8: =J7*Drivers!J8 -> 2608.8781
B9: Operations & support | D9: 1186 | E9: 1282 | F9: =F7*Drivers!F9 -> 1404.403 | G9: =G7*Drivers!G9 -> 1504.1767 | H9: =H7*Drivers!H9 -> 1610.1346 | I9: =I7*Drivers!I9 -> 1692.079 | J9: =J7*Drivers!J9 -> 1793.6037
B10: Product development | D10: 1722 | E10: 2056 | F10: =F7*Drivers!F10 -> 2198.196 | G10: =G7*Drivers!G10 -> 2329.4772 | H10: =H7*Drivers!H10 -> 2472.7067 | I10: =I7*Drivers!I10 -> 2615.0311 | J10: =J7*Drivers!J10 -> 2739.322
B11: Sales & marketing | D11: 1763 | E11: 2148 | F11: =F7*Drivers!F11 -> 2320.318 | G11: =G7*Drivers!G11 -> 2502.524 | H11: =H7*Drivers!H11 -> 2659.5973 | I11: =I7*Drivers!I11 -> 2815.0041 | J11: =J7*Drivers!J11 -> 2934.9879
B12: General & administrative | D12: 2025 | E12: 1185 | F12: =F7*Drivers!F12 -> 1282.281 | G12: =G7*Drivers!G12 -> 1371.0637 | H12: =H7*Drivers!H12 -> 1466.3726 | I12: =I7*Drivers!I12 -> 1538.2536 | J12: =J7*Drivers!J12 -> 1630.5488
B13: Total costs & expenses | D13: =SUM(D8:D12) -> 8399 | E13: =SUM(E8:E12) -> 8549 | F13: =SUM(F8:F12) -> 9220.211 | G13: =SUM(G8:G12) -> 9876.9831 | H13: =SUM(H8:H12) -> 10537.756 | I13: =SUM(I8:I12) -> 11121.574 | J13: =SUM(J8:J12) -> 11707.34
B14: Income from operations (EBIT) | D14: =D7-D13 -> 1518 | E14: =E7-E13 -> 2553 | F14: =F7-F13 -> 2991.989 | G14: =G7-G13 -> 3434.3149 | H14: =H7-H13 -> 3838.4459 | I14: =I7-I13 -> 4260.9625 | J14: =J7-J13 -> 4598.1477
B16: Interest income | D16: 721 | E16: 818 | F16: =Drivers!F15*('Balance Sheet'!E8+'Balance Sheet'!E9) -> 424.44 | G16: =Drivers!G15*('Balance Sheet'!F8+'Balance Sheet'!F9) -> 602.99326 | H16: =Drivers!H15*('Balance Sheet'!G8+'Balance Sheet'!G9) -> 763.49034 | I16: =Drivers!I15*('Balance Sheet'!H8+'Balance Sheet'!H9) -> 972.41558 | J16: =Drivers!J15*('Balance Sheet'!I8+'Balance Sheet'!I9) -> 1200.6599
B17: Interest expense | D17: -83 | E17: 0 | F17: =-Drivers!F31*'Balance Sheet'!E23 -> 0 | G17: =-Drivers!G31*'Balance Sheet'!F23 -> 0 | H17: =-Drivers!H31*'Balance Sheet'!G23 -> 0 | I17: =-Drivers!I31*'Balance Sheet'!H23 -> 0 | J17: =-Drivers!J31*'Balance Sheet'!I23 -> 0
B18: Other income/(expense), net | D18: -54 | E18: -40 | F18: =Drivers!F16 -> -40 | G18: =Drivers!G16 -> -40 | H18: =Drivers!H16 -> -40 | I18: =Drivers!I16 -> -40 | J18: =Drivers!J16 -> -40
B19: Pre-tax income (EBT) | D19: =D14+D16+D17+D18 -> 2102 | E19: =E14+E16+E17+E18 -> 3331 | F19: =F14+F16+F17+F18 -> 3376.429 | G19: =G14+G16+G17+G18 -> 3997.3081 | H19: =H14+H16+H17+H18 -> 4561.9362 | I19: =I14+I16+I17+I18 -> 5193.378 | J19: =J14+J16+J17+J18 -> 5758.8076
B20: Income tax provision | D20: 2690 | E20: -683 | F20: =-F19*Drivers!F14 -> -742.81438 | G20: =-G19*Drivers!G14 -> -879.40779 | H20: =-H19*Drivers!H14 -> -1003.626 | I20: =-I19*Drivers!I14 -> -1142.5432 | J20: =-J19*Drivers!J14 -> -1266.9377
B21: Net income | D21: =D19+D20 -> 4792 | E21: =E19+E20 -> 2648 | F21: =F19+F20 -> 2633.6146 | G21: =G19+G20 -> 3117.9003 | H21: =H19+H20 -> 3558.3103 | I21: =I19+I20 -> 4050.8349 | J21: =J19+J20 -> 4491.8699
B23: Memo: EBIT margin | D23: =D14/D7 -> 0.15307049 | E23: =E14/E7 -> 0.22995857 | F23: =F14/F7 -> 0.245 | G23: =G14/G7 -> 0.258 | H23: =H14/H7 -> 0.267 | I23: =I14/I7 -> 0.277 | J23: =J14/J7 -> 0.282
B24: Memo: Net income margin | D24: =D21/D7 -> 0.48321065 | E24: =E21/E7 -> 0.23851558 | F24: =F21/F7 -> 0.2156544 | G24: =G21/G7 -> 0.23422963 | H24: =H21/H7 -> 0.24751393 | I24: =I21/I7 -> 0.26333986 | J24: =J21/J7 -> 0.27548209
B25: Memo: Revenue growth | D25: n/a | E25: =E7/D7-1 -> 0.11949178 | F25: =F7/E7-1 -> 0.1 | G25: =G7/F7-1 -> 0.09 | H25: =H7/G7-1 -> 0.08 | I25: =I7/H7-1 -> 0.07 | J25: =J7/I7-1 -> 0.06

Sheet Balance Sheet
B2: Balance Sheet
D4: 2023 | E4: =D4+1 -> 2024 | F4: =E4+1 -> 2025 | G4: =F4+1 -> 2026 | H4: =G4+1 -> 2027 | I4: =H4+1 -> 2028 | J4: =I4+1 -> 2029
C5: ($ in millions) | D5: ="FY"&D4&"A" -> FY2023A | E5: ="FY"&E4&"A" -> FY2024A | F5: ="FY"&F4&"E" -> FY2025E | G5: ="FY"&G4&"E" -> FY2026E | H5: ="FY"&H4&"E" -> FY2027E | I5: ="FY"&I4&"E" -> FY2028E | J5: ="FY"&J4&"E" -> FY2029E
B7: Assets
B8: Cash & cash equivalents | D8: 6874 | E8: 6864 | F8: ='Cash Flow'!F30 -> 11327.831 | G8: ='Cash Flow'!G30 -> 16344.851 | H8: ='Cash Flow'!H30 -> 21842.884 | I8: ='Cash Flow'!I30 -> 27849.313 | J8: ='Cash Flow'!J30 -> 34286.151
B9: Short-term investments | D9: 3197 | E9: 3747 | F9: =E9 -> 3747 | G9: =F9 -> 3747 | H9: =G9 -> 3747 | I9: =H9 -> 3747 | J9: =I9 -> 3747
B10: Funds receivable | D10: 5869 | E10: 5931 | F10: =E10 -> 5931 | G10: =F10 -> 5931 | H10: =G10 -> 5931 | I10: =H10 -> 5931 | J10: =I10 -> 5931
B11: Prepaids & other current assets | D11: 569 | E11: 638 | F11: ='Income Statement'!F7*Drivers!F23 -> 696.0954 | G11: ='Income Statement'!G7*Drivers!G23 -> 758.74399 | H11: ='Income Statement'!H7*Drivers!H23 -> 819.4435 | I11: ='Income Statement'!I7*Drivers!I23 -> 876.80455 | J11: ='Income Statement'!J7*Drivers!J23 -> 929.41282
B12: Total current assets | D12: =SUM(D8:D11) -> 16509 | E12: =SUM(E8:E11) -> 17180 | F12: =SUM(F8:F11) -> 21701.927 | G12: =SUM(G8:G11) -> 26781.595 | H12: =SUM(H8:H11) -> 32340.327 | I12: =SUM(I8:I11) -> 38404.118 | J12: =SUM(J8:J11) -> 44893.564
B13: Deferred tax assets | D13: 2881 | E13: 2439 | F13: =E13 -> 2439 | G13: =F13 -> 2439 | H13: =G13 -> 2439 | I13: =H13 -> 2439 | J13: =I13 -> 2439
B14: Goodwill & intangibles, net | D14: 792 | E14: 777 | F14: =E14 -> 777 | G14: =F14 -> 777 | H14: =G14 -> 777 | I14: =H14 -> 777 | J14: =I14 -> 777
B15: Other noncurrent assets (incl. PP&E) | D15: 463 | E15: 563 | F15: =E15-'Cash Flow'!F20-'Cash Flow'!F9 -> 550.7878 | G15: =F15-'Cash Flow'!G20-'Cash Flow'!G9 -> 537.4765 | H15: =G15-'Cash Flow'!H20-'Cash Flow'!H9 -> 523.1003 | I15: =H15-'Cash Flow'!I20-'Cash Flow'!I9 -> 507.71776 | J15: =I15-'Cash Flow'!J20-'Cash Flow'!J9 -> 491.41228
B16: Total assets | D16: =D12+D13+D14+D15 -> 20645 | E16: =E12+E13+E14+E15 -> 20959 | F16: =F12+F13+F14+F15 -> 25468.715 | G16: =G12+G13+G14+G15 -> 30535.071 | H16: =H12+H13+H14+H15 -> 36079.427 | I16: =I12+I13+I14+I15 -> 42127.836 | J16: =J12+J13+J14+J15 -> 48600.976
B18: Liabilities & Stockholders' Equity
B19: Accrued exp & other current liab. | D19: 2654 | E19: 2614 | F19: ='Income Statement'!F7*Drivers!F24 -> 2869.867 | G19: ='Income Statement'!G7*Drivers!G24 -> 3128.155 | H19: ='Income Statement'!H7*Drivers!H24 -> 3378.4074 | I19: ='Income Statement'!I7*Drivers!I24 -> 3614.896 | J19: ='Income Statement'!J7*Drivers!J24 -> 3831.7897
B20: Funds payable | D20: 5869 | E20: 5931 | F20: =F10 -> 5931 | G20: =G10 -> 5931 | H20: =H10 -> 5931 | I20: =I10 -> 5931 | J20: =J10 -> 5931
B21: Unearned fees (deferred revenue) | D21: 1427 | E21: 1616 | F21: ='Income Statement'!F7*Drivers!F25 -> 1770.769 | G21: ='Income Statement'!G7*Drivers!G25 -> 1930.1382 | H21: ='Income Statement'!H7*Drivers!H25 -> 2084.5493 | I21: ='Income Statement'!I7*Drivers!I25 -> 2230.4677 | J21: ='Income Statement'!J7*Drivers!J25 -> 2364.2958
B22: Total current liabilities | D22: =SUM(D19:D21) -> 9950 | E22: =SUM(E19:E21) -> 10161 | F22: =SUM(F19:F21) -> 10571.636 | G22: =SUM(G19:G21) -> 10989.293 | H22: =SUM(H19:H21) -> 11393.957 | I22: =SUM(I19:I21) -> 11776.364 | J22: =SUM(J19:J21) -> 12127.085
B23: Long-term debt | D23: 1991 | E23: 1995 | F23: =E23 -> 1995 | G23: =F23 -> 1995 | H23: =G23 -> 1995 | I23: =H23 -> 1995 | J23: =I23 -> 1995
B24: Other noncurrent liabilities | D24: 539 | E24: 391 | F24: =E24 -> 391 | G24: =F24 -> 391 | H24: =G24 -> 391 | I24: =H24 -> 391 | J24: =I24 -> 391
B25: Total liabilities | D25: =D22+D23+D24 -> 12480 | E25: =E22+E23+E24 -> 12547 | F25: =F22+F23+F24 -> 12957.636 | G25: =G22+G23+G24 -> 13375.293 | H25: =H22+H23+H24 -> 13779.957 | I25: =I22+I23+I24 -> 14162.364 | J25: =J22+J23+J24 -> 14513.085
B27: Additional paid-in capital | D27: 11639 | E27: 12602 | F27: =E27+'Cash Flow'!F10 -> 14067.464 | G27: =F27+'Cash Flow'!G10 -> 15598.263 | H27: =G27+'Cash Flow'!H10 -> 17179.645 | I27: =H27+'Cash Flow'!I10 -> 18794.812 | J27: =I27+'Cash Flow'!J10 -> 20425.361
B28: Accumulated deficit | D28: -3425 | E28: -4154 | F28: =E28+'Income Statement'!F21 -> -1520.3854 | G28: =F28+'Income Statement'!G21 -> 1597.515 | H28: =G28+'Income Statement'!H21 -> 5155.8252 | I28: =H28+'Income Statement'!I21 -> 9206.6601 | J28: =I28+'Income Statement'!J21 -> 13698.53
B29: Accumulated OCI | D29: -49 | E29: -36 | F29: =E29 -> -36 | G29: =F29 -> -36 | H29: =G29 -> -36 | I29: =H29 -> -36 | J29: =I29 -> -36
B30: Total stockholders' equity | D30: =D27+D28+D29 -> 8165 | E30: =E27+E28+E29 -> 8412 | F30: =F27+F28+F29 -> 12511.079 | G30: =G27+G28+G29 -> 17159.778 | H30: =H27+H28+H29 -> 22299.471 | I30: =I27+I28+I29 -> 27965.472 | J30: =J27+J28+J29 -> 34087.891
B31: Total liabilities & equity | D31: =D25+D30 -> 20645 | E31: =E25+E30 -> 20959 | F31: =F25+F30 -> 25468.715 | G31: =G25+G30 -> 30535.071 | H31: =H25+H30 -> 36079.427 | I31: =I25+I30 -> 42127.836 | J31: =J25+J30 -> 48600.976
B33: Balance check (A - L&E) | D33: =D16-D31 -> 0 | E33: =E16-E31 -> 0 | F33: =F16-F31 -> 0 | G33: =G16-G31 -> 0 | H33: =H16-H31 -> 0 | I33: =I16-I31 -> 0 | J33: =J16-J31 -> 0

Sheet Cash Flow
B2: Cash Flow Statement
D4: 2023 | E4: =D4+1 -> 2024 | F4: =E4+1 -> 2025 | G4: =F4+1 -> 2026 | H4: =G4+1 -> 2027 | I4: =H4+1 -> 2028 | J4: =I4+1 -> 2029
C5: ($ in millions) | D5: ="FY"&D4&"A" -> FY2023A | E5: ="FY"&E4&"A" -> FY2024A | F5: ="FY"&F4&"E" -> FY2025E | G5: ="FY"&G4&"E" -> FY2026E | H5: ="FY"&H4&"E" -> FY2027E | I5: ="FY"&I4&"E" -> FY2028E | J5: ="FY"&J4&"E" -> FY2029E
B7: Operating activities
B8: Net income | D8: ='Income Statement'!D21 -> 4792 | E8: ='Income Statement'!E21 -> 2648 | F8: ='Income Statement'!F21 -> 2633.6146 | G8: ='Income Statement'!G21 -> 3117.9003 | H8: ='Income Statement'!H21 -> 3558.3103 | I8: ='Income Statement'!I21 -> 4050.8349 | J8: ='Income Statement'!J21 -> 4491.8699
B9: Depreciation & amortization | D9: 44 | E9: 65 | F9: ='Income Statement'!F7*Drivers!F18 -> 61.061 | G9: ='Income Statement'!G7*Drivers!G18 -> 66.55649 | H9: ='Income Statement'!H7*Drivers!H18 -> 71.881009 | I9: ='Income Statement'!I7*Drivers!I18 -> 76.91268 | J9: ='Income Statement'!J7*Drivers!J18 -> 81.527441
B10: Stock-based compensation | D10: 1120 | E10: 1407 | F10: ='Income Statement'!F7*Drivers!F20 -> 1465.464 | G10: ='Income Statement'!G7*Drivers!G20 -> 1530.7993 | H10: ='Income Statement'!H7*Drivers!H20 -> 1581.3822 | I10: ='Income Statement'!I7*Drivers!I20 -> 1615.1663 | J10: ='Income Statement'!J7*Drivers!J20 -> 1630.5488
B11: Deferred income taxes & other non-cash | D11: -2792 | E11: 465 | F11: 0 | G11: 0 | H11: 0 | I11: 0 | J11: 0
B12: Chg in prepaids & other assets | D12: -102 | E12: -163 | F12: =-('Balance Sheet'!F11-'Balance Sheet'!E11) -> -58.0954 | G12: =-('Balance Sheet'!G11-'Balance Sheet'!F11) -> -62.648586 | H12: =-('Balance Sheet'!H11-'Balance Sheet'!G11) -> -60.699519 | I12: =-('Balance Sheet'!I11-'Balance Sheet'!H11) -> -57.361045 | J12: =-('Balance Sheet'!J11-'Balance Sheet'!I11) -> -52.608273
B13: Chg in accrued & other liabilities | D13: 580 | E13: -104 | F13: ='Balance Sheet'!F19-'Balance Sheet'!E19 -> 255.867 | G13: ='Balance Sheet'!G19-'Balance Sheet'!F19 -> 258.28803 | H13: ='Balance Sheet'!H19-'Balance Sheet'!G19 -> 250.2524 | I13: ='Balance Sheet'!I19-'Balance Sheet'!H19 -> 236.48852 | J13: ='Balance Sheet'!J19-'Balance Sheet'!I19 -> 216.89376
B14: Chg in unearned fees | D14: 242 | E14: 200 | F14: ='Balance Sheet'!F21-'Balance Sheet'!E21 -> 154.769 | G14: ='Balance Sheet'!G21-'Balance Sheet'!F21 -> 159.36921 | H14: ='Balance Sheet'!H21-'Balance Sheet'!G21 -> 154.41106 | I14: ='Balance Sheet'!I21-'Balance Sheet'!H21 -> 145.91845 | J14: ='Balance Sheet'!J21-'Balance Sheet'!I21 -> 133.82806
B15: Cash from operations | D15: =SUM(D8:D14) -> 3884 | E15: =SUM(E8:E14) -> 4518 | F15: =SUM(F8:F14) -> 4512.6802 | G15: =SUM(G8:G14) -> 5070.2648 | H15: =SUM(H8:H14) -> 5555.5374 | I15: =SUM(I8:I14) -> 6067.9598 | J15: =SUM(J8:J14) -> 6502.0597
B17: Investing activities
B18: Purchases of ST investments | D18: -3308 | E18: -3146 | F18: 0 | G18: 0 | H18: 0 | I18: 0 | J18: 0
B19: Sales & maturities of ST investments | D19: 2380 | E19: 2605 | F19: 0 | G19: 0 | H19: 0 | I19: 0 | J19: 0
B20: Capex & other investing, net | D20: -114 | E20: -75 | F20: =-'Income Statement'!F7*Drivers!F19 -> -48.8488 | G20: =-'Income Statement'!G7*Drivers!G19 -> -53.245192 | H20: =-'Income Statement'!H7*Drivers!H19 -> -57.504807 | I20: =-'Income Statement'!I7*Drivers!I19 -> -61.530144 | J20: =-'Income Statement'!J7*Drivers!J19 -> -65.221953
B21: Cash from investing | D21: =SUM(D18:D20) -> -1042 | E21: =SUM(E18:E20) -> -616 | F21: =SUM(F18:F20) -> -48.8488 | G21: =SUM(G18:G20) -> -53.245192 | H21: =SUM(H18:H20) -> -57.504807 | I21: =SUM(I18:I20) -> -61.530144 | J21: =SUM(J18:J20) -> -65.221953
B23: Financing activities
B24: Share repurchases | D24: -2250 | E24: -3430 | F24: 0 | G24: 0 | H24: 0 | I24: 0 | J24: 0
B25: Taxes on equity awards, funds flow & FX, net | D25: -1096 | E25: -482 | F25: 0 | G25: 0 | H25: 0 | I25: 0 | J25: 0
B26: Cash from financing | D26: =D24+D25 -> -3346 | E26: =E24+E25 -> -3912 | F26: =F24+F25 -> 0 | G26: =G24+G25 -> 0 | H26: =H24+H25 -> 0 | I26: =I24+I25 -> 0 | J26: =J24+J25 -> 0
B28: Net change in cash | D28: =D15+D21+D26 -> -504 | E28: =E15+E21+E26 -> -10 | F28: =F15+F21+F26 -> 4463.8314 | G28: =G15+G21+G26 -> 5017.0196 | H28: =H15+H21+H26 -> 5498.0326 | I28: =I15+I21+I26 -> 6006.4296 | J28: =J15+J21+J26 -> 6436.8377
B29: Beginning cash | D29: 7378 | E29: 6874 | F29: ='Balance Sheet'!E8 -> 6864 | G29: ='Balance Sheet'!F8 -> 11327.831 | H29: ='Balance Sheet'!G8 -> 16344.851 | I29: ='Balance Sheet'!H8 -> 21842.884 | J29: ='Balance Sheet'!I8 -> 27849.313
B30: Ending cash | D30: =D29+D28 -> 6874 | E30: =E29+E28 -> 6864 | F30: =F29+F28 -> 11327.831 | G30: =G29+G28 -> 16344.851 | H30: =H29+H28 -> 21842.884 | I30: =I29+I28 -> 27849.313 | J30: =J29+J28 -> 34286.151

Sheet DCF
B2: DCF Valuation - Unlevered Free Cash Flow
C3: ($ in millions, except per share)
B6: Cost of Capital (WACC)
B7: Risk-free rate | D7: =Drivers!D28 -> 0.043
B8: Beta | D8: =Drivers!D30 -> 1.25
B9: Equity risk premium | D9: =Drivers!D29 -> 0.05
B10: Cost of equity | D10: =D7+D8*D9 -> 0.1055
B11: Pre-tax cost of debt | D11: =Drivers!D31 -> 0.05
B12: Tax rate | D12: =Drivers!F14 -> 0.22
B13: After-tax cost of debt | D13: =D11*(1-D12) -> 0.039
B14: Market capitalization | D14: =Drivers!D33*Drivers!D34 -> 80010
B15: Total debt | D15: ='Balance Sheet'!E23 -> 1995
B16: Equity weight | D16: =D14/(D14+D15) -> 0.97567222
B17: Debt weight | D17: =D15/(D14+D15) -> 0.024327785
B18: WACC | D18: =D16*D10+D17*D13 -> 0.1038822
B21: Unlevered Free Cash Flow
F22: ="FY"&'Income Statement'!F4&"E" -> FY2025E | G22: ="FY"&'Income Statement'!G4&"E" -> FY2026E | H22: ="FY"&'Income Statement'!H4&"E" -> FY2027E | I22: ="FY"&'Income Statement'!I4&"E" -> FY2028E | J22: ="FY"&'Income Statement'!J4&"E" -> FY2029E
B23: EBIT | F23: ='Income Statement'!F14 -> 2991.989 | G23: ='Income Statement'!G14 -> 3434.3149 | H23: ='Income Statement'!H14 -> 3838.4459 | I23: ='Income Statement'!I14 -> 4260.9625 | J23: ='Income Statement'!J14 -> 4598.1477
B24: Less: cash taxes on EBIT | F24: =-F23*$D$12 -> -658.23758 | G24: =-G23*$D$12 -> -755.54927 | H24: =-H23*$D$12 -> -844.4581 | I24: =-I23*$D$12 -> -937.41174 | J24: =-J23*$D$12 -> -1011.5925
B25: NOPAT | F25: =F23+F24 -> 2333.7514 | G25: =G23+G24 -> 2678.7656 | H25: =H23+H24 -> 2993.9878 | I25: =I23+I24 -> 3323.5507 | J25: =J23+J24 -> 3586.5552
B26: Plus: D&A | F26: ='Cash Flow'!F9 -> 61.061 | G26: ='Cash Flow'!G9 -> 66.55649 | H26: ='Cash Flow'!H9 -> 71.881009 | I26: ='Cash Flow'!I9 -> 76.91268 | J26: ='Cash Flow'!J9 -> 81.527441
B27: Less: capex | F27: ='Cash Flow'!F20 -> -48.8488 | G27: ='Cash Flow'!G20 -> -53.245192 | H27: ='Cash Flow'!H20 -> -57.504807 | I27: ='Cash Flow'!I20 -> -61.530144 | J27: ='Cash Flow'!J20 -> -65.221953
B28: Less: chg in net working capital | F28: ='Cash Flow'!F12+'Cash Flow'!F13+'Cash Flow'!F14 -> 352.5406 | G28: ='Cash Flow'!G12+'Cash Flow'!G13+'Cash Flow'!G14 -> 355.00865 | H28: ='Cash Flow'!H12+'Cash Flow'!H13+'Cash Flow'!H14 -> 343.96394 | I28: ='Cash Flow'!I12+'Cash Flow'!I13+'Cash Flow'!I14 -> 325.04592 | J28: ='Cash Flow'!J12+'Cash Flow'!J13+'Cash Flow'!J14 -> 298.11355
B29: Unlevered free cash flow | F29: =F25+F26+F27+F28 -> 2698.5042 | G29: =G25+G26+G27+G28 -> 3047.0856 | H29: =H25+H26+H27+H28 -> 3352.3279 | I29: =I25+I26+I27+I28 -> 3663.9792 | J29: =J25+J26+J27+J28 -> 3900.9742
B30: Discount period | F30: 1 | G30: 2 | H30: 3 | I30: 4 | J30: 5
B31: Discount factor | F31: =1/(1+$D$18)^F30 -> 0.90589376 | G31: =1/(1+$D$18)^G30 -> 0.82064351 | H31: =1/(1+$D$18)^H30 -> 0.74341583 | I31: =1/(1+$D$18)^I30 -> 0.67345576 | J31: =1/(1+$D$18)^J30 -> 0.61007938
B32: PV of FCF | F32: =F29*F31 -> 2444.5581 | G32: =G29*G31 -> 2500.571 | H32: =H29*H31 -> 2492.1737 | I32: =I29*I31 -> 2467.5279 | J32: =J29*J31 -> 2379.9039
B35: Valuation
B36: Terminal growth rate | D36: =Drivers!D32 -> 0.03
B37: Terminal value (Gordon) | D37: =J29*(1+D36)/(D18-D36) -> 54383.915
B38: PV of terminal value | D38: =D37*J31 -> 33178.505
B39: Sum of PV of FCF | D39: =SUM(F32:J32) -> 12284.735
B40: Enterprise value | D40: =D38+D39 -> 45463.24
B41: Plus: cash & ST investments | D41: ='Balance Sheet'!E8+'Balance Sheet'!E9 -> 10611
B42: Less: total debt | D42: =-'Balance Sheet'!E23 -> -1995
B43: Equity value | D43: =D40+D41+D42 -> 54079.24
B44: Diluted shares (mm) | D44: =Drivers!D34 -> 635
B45: Implied value per share | D45: =D43/D44 -> 85.164157
B46: Current share price | D46: =Drivers!D33 -> 126
B47: Implied upside / (downside) | D47: =D45/D46-1 -> -0.32409399
...
