Workbook

Sheet Cover
A1: Palantir Technologies Inc. (PLTR) — Banker-Style EDGAR-Tied Model
A3: Model status | B3: Historical actuals tied to EDGAR / official 10-K; forecast/DCF assumptions separated.
A4: Currency / units | B4: $ in millions except per-share and share-count data
A5: Historical period | B5: FY2023A–FY2025A
A6: Forecast period | B6: FY2026E–FY2030E
A7: Primary sources | B7: FY2025 Form 10-K PDF and FY2024 Form 10-K HTML for FY2023 balance sheet.
A8: Key analytical focus | B8: AI-driven revenue growth, government/commercial mix, SBC normalization, margin expansion, net-cash balance sheet, and DCF sensitivity.
A10: Color convention
A11: Blue font | B11: Hardcoded inputs / assumptions
A12: Black font | B12: Formulas
A13: Fix status | B13: Patched forecast interest income to prior-period cash/securities and corrected DCF equity bridge links.
A14: Formula scan | B14: No formula-error strings found after patch.

Sheet Inputs
A1: Palantir Forecast Assumptions
A3: Metric | B3: 2026E | C3: 2027E | D3: 2028E | E3: 2029E | F3: 2030E | G3: Source / rationale | H3: Model treatment | I3: Status
A4: Revenue growth | B4: 0.35 | C4: 0.28 | D4: 0.22 | E4: 0.18 | F4: 0.15 | G4: Assumption; decelerates from FY2025 56% actual growth. | H4: Revenue forecast | I4: Assumption
A5: Cost of revenue % revenue | B5: 0.175 | C5: 0.17 | D5: 0.168 | E5: 0.165 | F5: 0.162 | G5: Assumption based on recent gross margin trend. | H5: Gross profit | I5: Assumption
A6: Sales & marketing % revenue | B6: 0.225 | C6: 0.215 | D6: 0.205 | E6: 0.195 | F6: 0.185 | G6: Assumption; operating leverage over forecast. | H6: Operating expense | I6: Assumption
A7: R&D % revenue | B7: 0.118 | C7: 0.115 | D7: 0.112 | E7: 0.11 | F7: 0.108 | G7: Assumption; sustained product investment. | H7: Operating expense | I7: Assumption
A8: G&A % revenue | B8: 0.142 | C8: 0.135 | D8: 0.13 | E8: 0.125 | F8: 0.12 | G8: Assumption; fixed-cost leverage. | H8: Operating expense | I8: Assumption
A9: Interest income % cash + securities | B9: 0.03 | C9: 0.027 | D9: 0.024 | E9: 0.022 | F9: 0.02 | G9: Assumption; yield declines over time. | H9: Non-operating income | I9: Assumption
A10: Other income / (expense) | B10: 0 | C10: 0 | D10: 0 | E10: 0 | F10: 0 | G10: Assumption; no recurring non-operating gain/loss forecast. | H10: Non-operating income | I10: Assumption
A11: Tax rate | B11: 0.03 | C11: 0.05 | D11: 0.08 | E11: 0.1 | F11: 0.12 | G11: Assumption; tax rate normalizes over time. | H11: Tax expense | I11: Assumption
A12: NCI % net income | B12: 0.006 | C12: 0.006 | D12: 0.006 | E12: 0.006 | F12: 0.006 | G12: Assumption based on recent NCI share. | H12: NCI bridge | I12: Assumption
A13: Diluted share count growth | B13: 0.025 | C13: 0.02 | D13: 0.018 | E13: 0.015 | F13: 0.012 | G13: Assumption; SBC dilution partially offset by repurchases. | H13: EPS denominator | I13: Assumption
A14: Capex % revenue | B14: 0.008 | C14: 0.008 | D14: 0.008 | E14: 0.008 | F14: 0.008 | G14: Assumption; asset-light software model. | H14: FCF forecast | I14: Assumption
A15: D&A % revenue | B15: 0.006 | C15: 0.006 | D15: 0.006 | E15: 0.006 | F15: 0.006 | G15: Assumption; approximates recent D&A intensity. | H15: CFO bridge | I15: Assumption
... A20: Customer deposits % revenue | B20: 0.075 | C20: 0.07 | D20: 0.065 | E20: 0.06 | F20: 0.055 | G20: Assumption. | H20: Balance sheet forecast | I20: Assumption
A21: WACC | B21: 0.095 | G21: Assumption. | H21: DCF | I21: Assumption
A22: Terminal growth rate | B22: 0.035 | G22: Assumption. | H22: DCF | I22: Assumption
A23: Diluted shares for valuation | B23: 2565.197 | G23: FY2025 diluted shares from 10-K, in millions. | H23: Equity bridge | I23: Historical actual base
A24: Cash + marketable securities | B24: 7177.043 | G24: FY2025 cash + marketable securities from 10-K. | H24: Equity bridge | I24: Historical actual
A25: Debt | B25: 0 | G25: FY2025 10-K notes no outstanding debt under credit facility. | H25: Equity bridge | I25: Historical actual

Sheet Historical Financials
A1: Palantir Historical Actuals — EDGAR / 10-K Tied
A3: $mm except per share / shares | B3: 2023A | C3: 2024A | D3: 2025A | E3: Source | F3: Tie-out check | G3: Notes
A4: Income Statement
A5: Revenue | B5: 2225.012 | C5: 2865.507 | D5: 4475.446 | E5: FY2025 10-K / FY2024 10-K | F5: =IF(AND(ISNUMBER(B5),ISNUMBER(C5),ISNUMBER(D5)),"PASS","CHECK") -> PASS
A6: Cost of revenue | B6: 431.105 | C6: 565.99 | D6: 789.177 | E6: FY2025 10-K / FY2024 10-K | F6: =IF(AND(ISNUMBER(B6),ISNUMBER(C6),ISNUMBER(D6)),"PASS","CHECK") -> PASS
A7: Gross profit | B7: 1793.907 | C7: 2299.517 | D7: 3686.269 | E7: FY2025 10-K / FY2024 10-K | F7: =IF(AND(ISNUMBER(B7),ISNUMBER(C7),ISNUMBER(D7)),"PASS","CHECK") -> PASS
A8: Sales and marketing | B8: 744.992 | C8: 887.755 | D8: 1056.859 | E8: FY2025 10-K / FY2024 10-K | F8: =IF(AND(ISNUMBER(B8),ISNUMBER(C8),ISNUMBER(D8)),"PASS","CHECK") -> PASS
A9: Research and development | B9: 404.624 | C9: 507.878 | D9: 557.677 | E9: FY2025 10-K / FY2024 10-K | F9: =IF(AND(ISNUMBER(B9),ISNUMBER(C9),ISNUMBER(D9)),"PASS","CHECK") -> PASS
A10: General and administrative | B10: 524.325 | C10: 593.481 | D10: 657.718 | E10: FY2025 10-K / FY2024 10-K | F10: =IF(AND(ISNUMBER(B10),ISNUMBER(C10),ISNUMBER(D10)),"PASS","CHECK") -> PASS
A11: Total operating expenses | B11: 1673.941 | C11: 1989.114 | D11: 2272.254 | E11: FY2025 10-K / FY2024 10-K | F11: =IF(AND(ISNUMBER(B11),ISNUMBER(C11),ISNUMBER(D11)),"PASS","CHECK") -> PASS
A12: Income from operations | B12: 119.966 | C12: 310.403 | D12: 1414.015 | E12: FY2025 10-K / FY2024 10-K | F12: =IF(AND(ISNUMBER(B12),ISNUMBER(C12),ISNUMBER(D12)),"PASS","CHECK") -> PASS
A13: Interest income | B13: 132.572 | C13: 196.792 | D13: 229.181 | E13: FY2025 10-K / FY2024 10-K | F13: =IF(AND(ISNUMBER(B13),ISNUMBER(C13),ISNUMBER(D13)),"PASS","CHECK") -> PASS
A14: Other income / (expense), net | B14: -15.447 | C14: -18.022 | D14: 14.172 | E14: FY2025 10-K / FY2024 10-K | F14: =IF(AND(ISNUMBER(B14),ISNUMBER(C14),ISNUMBER(D14)),"PASS","CHECK") -> PASS
A15: Income before taxes | B15: 237.091 | C15: 489.173 | D15: 1657.368 | E15: FY2025 10-K / FY2024 10-K | F15: =IF(AND(ISNUMBER(B15),ISNUMBER(C15),ISNUMBER(D15)),"PASS","CHECK") -> PASS
A16: Provision for income taxes | B16: 19.716 | C16: 21.255 | D16: 22.724 | E16: FY2025 10-K / FY2024 10-K | F16: =IF(AND(ISNUMBER(B16),ISNUMBER(C16),ISNUMBER(D16)),"PASS","CHECK") -> PASS
... A20: Diluted shares | B20: 2297.927 | C20: 2450.818 | D20: 2565.197 | E20: FY2025 10-K / FY2024 10-K | F20: =IF(AND(ISNUMBER(B20),ISNUMBER(C20),ISNUMBER(D20)),"PASS","CHECK") -> PASS
A21: Balance Sheet
A22: Cash and cash equivalents | B22: 831.047 | C22: 2098.524 | D22: 1423.796 | E22: FY2025 10-K / FY2024 10-K | F22: =IF(AND(ISNUMBER(B22),ISNUMBER(C22),ISNUMBER(D22)),"PASS","CHECK") -> PASS
A23: Marketable securities | B23: 2843.132 | C23: 3131.463 | D23: 5753.247 | E23: FY2025 10-K / FY2024 10-K | F23: =IF(AND(ISNUMBER(B23),ISNUMBER(C23),ISNUMBER(D23)),"PASS","CHECK") -> PASS
A24: Accounts receivable | B24: 364.784 | C24: 575.048 | D24: 1042.065 | E24: FY2025 10-K / FY2024 10-K | F24: =IF(AND(ISNUMBER(B24),ISNUMBER(C24),ISNUMBER(D24)),"PASS","CHECK") -> PASS
A25: Prepaids & other current assets | B25: 99.655 | C25: 129.254 | D25: 139.066 | E25: FY2025 10-K / FY2024 10-K | F25: =IF(AND(ISNUMBER(B25),ISNUMBER(C25),ISNUMBER(D25)),"PASS","CHECK") -> PASS
A26: Total current assets | B26: 4138.618 | C26: 5934.289 | D26: 8358.174 | E26: FY2025 10-K / FY2024 10-K | F26: =IF(AND(ISNUMBER(B26),ISNUMBER(C26),ISNUMBER(D26)),"PASS","CHECK") -> PASS
A27: Property and equipment, net | B27: 47.758 | C27: 39.638 | D27: 51.96 | E27: FY2025 10-K / FY2024 10-K | F27: =IF(AND(ISNUMBER(B27),ISNUMBER(C27),ISNUMBER(D27)),"PASS","CHECK") -> PASS
A28: Operating lease ROU assets | B28: 182.863 | C28: 200.74 | D28: 200.105 | E28: FY2025 10-K / FY2024 10-K | F28: =IF(AND(ISNUMBER(B28),ISNUMBER(C28),ISNUMBER(D28)),"PASS","CHECK") -> PASS
A29: Other assets | B29: 153.186 | C29: 166.217 | D29: 290.153 | E29: FY2025 10-K / FY2024 10-K | F29: =IF(AND(ISNUMBER(B29),ISNUMBER(C29),ISNUMBER(D29)),"PASS","CHECK") -> PASS
A30: Total assets | B30: 4522.425 | C30: 6340.884 | D30: 8900.392 | E30: FY2025 10-K / FY2024 10-K | F30: =IF(AND(ISNUMBER(B30),ISNUMBER(C30),ISNUMBER(D30)),"PASS","CHECK") -> PASS
A31: Accounts payable | B31: 12.122 | C31: 0.103 | D31: 8.064 | E31: FY2025 10-K / FY2024 10-K | F31: =IF(AND(ISNUMBER(B31),ISNUMBER(C31),ISNUMBER(D31)),"PASS","CHECK") -> PASS
A32: Accrued liabilities | B32: 222.991 | C32: 427.046 | D32: 355.624 | E32: FY2025 10-K / FY2024 10-K | F32: =IF(AND(ISNUMBER(B32),ISNUMBER(C32),ISNUMBER(D32)),"PASS","CHECK") -> PASS
A33: Deferred revenue | B33: 246.901 | C33: 259.624 | D33: 408.963 | E33: FY2025 10-K / FY2024 10-K | F33: =IF(AND(ISNUMBER(B33),ISNUMBER(C33),ISNUMBER(D33)),"PASS","CHECK") -> PASS
... A49: Total liabilities and equity | B49: 4522.425 | C49: 6340.884 | D49: 8900.392 | E49: FY2025 10-K / FY2024 10-K | F49: =IF(AND(ISNUMBER(B49),ISNUMBER(C49),ISNUMBER(D49)),"PASS","CHECK") -> PASS
A50: Cash Flow Statement
A51: Net income | B51: 217.375 | C51: 467.918 | D51: 1634.644 | E51: FY2025 10-K / FY2024 10-K | F51: =IF(AND(ISNUMBER(B51),ISNUMBER(C51),ISNUMBER(D51)),"PASS","CHECK") -> PASS
A52: D&A | B52: 33.354 | C52: 31.587 | D52: 26.145 | E52: FY2025 10-K / FY2024 10-K | F52: =IF(AND(ISNUMBER(B52),ISNUMBER(C52),ISNUMBER(D52)),"PASS","CHECK") -> PASS
A53: Stock-based compensation | B53: 475.903 | C53: 691.638 | D53: 684.033 | E53: FY2025 10-K / FY2024 10-K | F53: =IF(AND(ISNUMBER(B53),ISNUMBER(C53),ISNUMBER(D53)),"PASS","CHECK") -> PASS
A54: Accounts receivable change | B54: -106.159 | C54: -211.157 | D54: -450.429 | E54: FY2025 10-K / FY2024 10-K | F54: =IF(AND(ISNUMBER(B54),ISNUMBER(C54),ISNUMBER(D54)),"PASS","CHECK") -> PASS
A55: Contract liabilities change | B55: 143.859 | C55: 76.796 | D55: 238.688 | E55: FY2025 10-K / FY2024 10-K | F55: =IF(AND(ISNUMBER(B55),ISNUMBER(C55),ISNUMBER(D55)),"PASS","CHECK") -> PASS
A56: Net cash provided by operating activities | B56: 712.183 | C56: 1153.865 | D56: 2134.473 | E56: FY2025 10-K / FY2024 10-K | F56: =IF(AND(ISNUMBER(B56),ISNUMBER(C56),ISNUMBER(D56)),"PASS","CHECK") -> PASS
A57: Purchases of property and equipment | B57: -15.114 | C57: -12.634 | D57: -33.882 | E57: FY2025 10-K / FY2024 10-K | F57: =IF(AND(ISNUMBER(B57),ISNUMBER(C57),ISNUMBER(D57)),"PASS","CHECK") -> PASS
A58: Net cash used in investing activities | B58: -2711.18 | C58: -340.655 | D58: -2783.551 | E58: FY2025 10-K / FY2024 10-K | F58: =IF(AND(ISNUMBER(B58),ISNUMBER(C58),ISNUMBER(D58)),"PASS","CHECK") -> PASS
A59: Net cash provided by / (used in) financing activities | B59: 218.839 | C59: 463.364 | D59: -26.91 | E59: FY2025 10-K / FY2024 10-K | F59: =IF(AND(ISNUMBER(B59),ISNUMBER(C59),ISNUMBER(D59)),"PASS","CHECK") -> PASS
...

Sheet Forecast Model
A1: Palantir Integrated Forecast Model
A3: $mm except per share / shares | B3: 2025A | C3: 2026E | D3: 2027E | E3: 2028E | F3: 2029E | G3: 2030E | H3: Source / formula | I3: Notes
A4: Income Statement
A5: Revenue | B5: ='Historical Financials'!D5 -> 4475.446 | C5: =B5*(1+Inputs!B4) -> 6041.8521 | D5: =C5*(1+Inputs!C4) -> 7733.5707 | E5: =D5*(1+Inputs!D4) -> 9434.9562 | F5: =E5*(1+Inputs!E4) -> 11133.248 | G5: =F5*(1+Inputs!F4) -> 12803.236 | H5: Historical; forecast via revenue growth
A6: Revenue growth | B6: =B5/'Historical Financials'!C5-1 -> 0.56183391 | C6: =C5/B5-1 -> 0.35 | D6: =D5/C5-1 -> 0.28 | E6: =E5/D5-1 -> 0.22 | F6: =F5/E5-1 -> 0.18 | G6: =G5/F5-1 -> 0.15 | H6: Formula
A7: Cost of revenue | B7: ='Historical Financials'!D6 -> 789.177 | C7: =C5*Inputs!B5 -> 1057.3241 | D7: =D5*Inputs!C5 -> 1314.707 | E7: =E5*Inputs!D5 -> 1585.0726 | F7: =F5*Inputs!E5 -> 1836.986 | G7: =G5*Inputs!F5 -> 2074.1242 | H7: Historical; forecast % revenue
A8: Cost of revenue % | B8: =B7/B5 -> 0.17633483 | C8: =C7/C5 -> 0.175 | D8: =D7/D5 -> 0.17 | E8: =E7/E5 -> 0.168 | F8: =F7/F5 -> 0.165 | G8: =G7/G5 -> 0.162 | H8: Formula
A9: Gross profit | B9: =B5-B7 -> 3686.269 | C9: =C5-C7 -> 4984.528 | D9: =D5-D7 -> 6418.8637 | E9: =E5-E7 -> 7849.8836 | F9: =F5-F7 -> 9296.2624 | G9: =G5-G7 -> 10729.111 | H9: Formula
A10: Gross margin | B10: =B9/B5 -> 0.82366517 | C10: =C9/C5 -> 0.825 | D10: =D9/D5 -> 0.83 | E10: =E9/E5 -> 0.832 | F10: =F9/F5 -> 0.835 | G10: =G9/G5 -> 0.838 | H10: Formula
A11: Sales and marketing | B11: ='Historical Financials'!D8 -> 1056.859 | C11: =C5*Inputs!B6 -> 1359.4167 | D11: =D5*Inputs!C6 -> 1662.7177 | E11: =E5*Inputs!D6 -> 1934.166 | F11: =F5*Inputs!E6 -> 2170.9834 | G11: =G5*Inputs!F6 -> 2368.5986 | H11: Historical; forecast % revenue
A12: S&M % revenue | B12: =B11/B5 -> 0.23614607 | C12: =C11/C5 -> 0.225 | D12: =D11/D5 -> 0.215 | E12: =E11/E5 -> 0.205 | F12: =F11/F5 -> 0.195 | G12: =G11/G5 -> 0.185 | H12: Formula
A13: Research and development | B13: ='Historical Financials'!D9 -> 557.677 | C13: =C5*Inputs!B7 -> 712.93855 | D13: =D5*Inputs!C7 -> 889.36063 | E13: =E5*Inputs!D7 -> 1056.7151 | F13: =F5*Inputs!E7 -> 1224.6573 | G13: =G5*Inputs!F7 -> 1382.7494 | H13: Historical; forecast % revenue
A14: R&D % revenue | B14: =B13/B5 -> 0.12460814 | C14: =C13/C5 -> 0.118 | D14: =D13/D5 -> 0.115 | E14: =E13/E5 -> 0.112 | F14: =F13/F5 -> 0.11 | G14: =G13/G5 -> 0.108 | H14: Formula
A15: General and administrative | B15: ='Historical Financials'!D10 -> 657.718 | C15: =C5*Inputs!B8 -> 857.943 | D15: =D5*Inputs!C8 -> 1044.032 | E15: =E5*Inputs!D8 -> 1226.5443 | F15: =F5*Inputs!E8 -> 1391.656 | G15: =G5*Inputs!F8 -> 1536.3883 | H15: Historical; forecast % revenue
A16: G&A % revenue | B16: =B15/B5 -> 0.14696144 | C16: =C15/C5 -> 0.142 | D16: =D15/D5 -> 0.135 | E16: =E15/E5 -> 0.13 | F16: =F15/F5 -> 0.125 | G16: =G15/G5 -> 0.12 | H16: Formula
A17: Operating income | B17: =B9-B11-B13-B15 -> 1414.015 | C17: =C9-C11-C13-C15 -> 2054.2297 | D17: =D9-D11-D13-D15 -> 2822.7533 | E17: =E9-E11-E13-E15 -> 3632.4582 | F17: =F9-F11-F13-F15 -> 4508.9656 | G17: =G9-G11-G13-G15 -> 5441.3751 | H17: Formula
A18: Operating margin | B18: =B17/B5 -> 0.31594952 | C18: =C17/C5 -> 0.34 | D18: =D17/D5 -> 0.365 | E18: =E17/E5 -> 0.385 | F18: =F17/F5 -> 0.405 | G18: =G17/G5 -> 0.425 | H18: Formula
A19: Interest income | B19: ='Historical Financials'!D13 -> 229.181 | C19: =(B40+B41)*Inputs!B9 -> 215.31129 | D19: =(C40+C41)*Inputs!C9 -> 274.40649 | E19: =(D40+D41)*Inputs!D9 -> 333.74929 | F19: =(E40+E41)*Inputs!E9 -> 402.8185 | G19: =(F40+F41)*Inputs!F9 -> 469.53557 | H19: Cash/securities yield
A20: Other income / (expense), net | B20: ='Historical Financials'!D14 -> 14.172 | C20: =Inputs!B10 -> 0 | D20: =Inputs!C10 -> 0 | E20: =Inputs!D10 -> 0 | F20: =Inputs!E10 -> 0 | G20: =Inputs!F10 -> 0 | H20: Assumption
A21: Pre-tax income | B21: =B17+B19+B20 -> 1657.368 | C21: =C17+C19+C20 -> 2269.541 | D21: =D17+D19+D20 -> 3097.1598 | E21: =E17+E19+E20 -> 3966.2074 | F21: =F17+F19+F20 -> 4911.7841 | G21: =G17+G19+G20 -> 5910.9107 | H21: Formula
A22: Tax expense | B22: ='Historical Financials'!D16 -> 22.724 | C22: =C21*Inputs!B11 -> 68.08623 | D22: =D21*Inputs!C11 -> 154.85799 | E22: =E21*Inputs!D11 -> 317.29659 | F22: =F21*Inputs!E11 -> 491.17841 | G22: =G21*Inputs!F11 -> 709.30929 | H22: Tax rate assumption
A23: Tax rate | B23: =B22/B21 -> 0.013710896 | C23: =C22/C21 -> 0.03 | D23: =D22/D21 -> 0.05 | E23: =E22/E21 -> 0.08 | F23: =F22/F21 -> 0.1 | G23: =G22/G21 -> 0.12 | H23: Formula
A24: Net income | B24: =B21-B22 -> 1634.644 | C24: =C21-C22 -> 2201.4548 | D24: =D21-D22 -> 2942.3018 | E24: =E21-E22 -> 3648.9108 | F24: =F21-F22 -> 4420.6057 | G24: =G21-G22 -> 5201.6014 | H24: Formula
A25: Less: NCI net income | B25: ='Historical Financials'!D18 -> 9.611 | C25: =C24*Inputs!B12 -> 13.208729 | D25: =D24*Inputs!C12 -> 17.653811 | E25: =E24*Inputs!D12 -> 21.893465 | F25: =F24*Inputs!E12 -> 26.523634 | G25: =G24*Inputs!F12 -> 31.209609 | H25: NCI assumption
A26: Net income attributable | B26: =B24-B25 -> 1625.033 | C26: =C24-C25 -> 2188.246 | D26: =D24-D25 -> 2924.648 | E26: =E24-E25 -> 3627.0174 | F26: =F24-F25 -> 4394.082 | G26: =G24-G25 -> 5170.3918 | H26: Formula
A27: Diluted shares | B27: ='Historical Financials'!D20 -> 2565.197 | C27: =B27*(1+Inputs!B13) -> 2629.3269 | D27: =C27*(1+Inputs!C13) -> 2681.9135 | E27: =D27*(1+Inputs!D13) -> 2730.1879 | F27: =E27*(1+Inputs!E13) -> 2771.1407 | G27: =F27*(1+Inputs!F13) -> 2804.3944 | H27: Share count assumption
A28: Diluted EPS | B28: =B26/B27 -> 0.63349248 | C28: =C26/C27 -> 0.83224571 | D28: =D26/D27 -> 1.090508 | E28: =E26/E27 -> 1.3284864 | F28: =F26/F27 -> 1.5856582 | G28: =G26/G27 -> 1.843675 | H28: Formula
A30: Cash Flow / Free Cash Flow
A31: D&A | B31: ='Historical Financials'!D52 -> 26.145 | C31: =C5*Inputs!B15 -> 36.251113 | D31: =D5*Inputs!C15 -> 46.401424 | E31: =E5*Inputs!D15 -> 56.609737 | F31: =F5*Inputs!E15 -> 66.79949 | G31: =G5*Inputs!F15 -> 76.819414 | H31: D&A % revenue
A32: Stock-based compensation | B32: ='Historical Financials'!D53 -> 684.033 | C32: =C5*Inputs!B16 -> 815.65003 | D32: =D5*Inputs!C16 -> 889.36063 | E32: =E5*Inputs!D16 -> 896.32084 | F32: =F5*Inputs!E16 -> 890.65987 | G32: =G5*Inputs!F16 -> 832.21032 | H32: SBC % revenue
A33: Working capital / other operating changes | B33: =0 -> 0 | C33: =C52-B52-(C42-B42) -> -199.9287 | D33: =D52-C52-(D42-C42) -> -208.35286 | E33: =E52-D52-(E42-D42) -> -224.58077 | F33: =F52-E52-(F42-E42) -> -222.53572 | G33: =G52-F52-(G42-F42) -> -182.05911 | H33: Simplified operating working-capital bridge
A34: Net cash provided by operating activities | B34: ='Historical Financials'!D56 -> 2134.473 | C34: =C24+C31+C32+C33 -> 2853.4272 | D34: =D24+D31+D32+D33 -> 3669.711 | E34: =E24+E31+E32+E33 -> 4377.2606 | F34: =F24+F31+F32+F33 -> 5155.5293 | G34: =G24+G31+G32+G33 -> 5928.572 | H34: Formula
A35: Capex | B35: ='Historical Financials'!D57 -> -33.882 | C35: =-C5*Inputs!B14 -> -48.334817 | D35: =-D5*Inputs!C14 -> -61.868566 | E35: =-E5*Inputs!D14 -> -75.47965 | F35: =-F5*Inputs!E14 -> -89.065987 | G35: =-G5*Inputs!F14 -> -102.42588 | H35: Capex % revenue
A36: Free cash flow | B36: =B34+B35 -> 2100.591 | C36: =C34+C35 -> 2805.0924 | D36: =D34+D35 -> 3607.8424 | E36: =E34+E35 -> 4301.781 | F36: =F34+F35 -> 5066.4633 | G36: =G34+G35 -> 5826.1462 | H36: CFO less capex
A37: SBC-adjusted FCF | B37: =B36-B32 -> 1416.558 | C37: =C36-C32 -> 1989.4424 | D37: =D36-D32 -> 2718.4818 | E37: =E36-E32 -> 3405.4602 | F37: =F36-F32 -> 4175.8035 | G37: =G36-G32 -> 4993.9358 | H37: FCF less SBC
A39: Balance Sheet
A40: Cash and cash equivalents | B40: ='Historical Financials'!D22 -> 1423.796 | C40: =C69-(C41+C42+C43+C45+C46+C47) -> 1604.8639 | D40: =D69-(D41+D42+D43+D45+D46+D47) -> 1740.0384 | E40: =E69-(E41+E42+E43+E45+E46+E47) -> 1841.9692 | F40: =F69-(F41+F42+F43+F45+F46+F47) -> 1942.3526 | G40: =G69-(G41+G42+G43+G45+G46+G47) -> 2002.6032 | H40: Historical actual; forecast cash balancing item | I40: Forecast cash is an explicit balancing item so projected balance sheet ties; historical cash is EDGAR-tied actual.
A41: Marketable securities | B41: ='Historical Financials'!D23 -> 5753.247 | C41: =B41+C36 -> 8558.3394 | D41: =C41+D36 -> 12166.182 | E41: =D41+E36 -> 16467.963 | F41: =E41+F36 -> 21534.426 | G41: =F41+G36 -> 27360.572 | H41: Assumes FCF is invested in securities
A42: Accounts receivable | B42: ='Historical Financials'!D24 -> 1042.065 | C42: =C5*Inputs!B17/365 -> 1407.0067 | D42: =D5*Inputs!C17/365 -> 1737.4049 | E42: =E5*Inputs!D17/365 -> 2067.9356 | F42: =F5*Inputs!E17/365 -> 2379.1599 | G42: =G5*Inputs!F17/365 -> 2630.8018 | H42: AR days
A43: Prepaids & other current assets | B43: ='Historical Financials'!D25 -> 139.066 | C43: =C5*Inputs!B18 -> 181.25556 | D43: =D5*Inputs!C18 -> 232.00712 | E43: =E5*Inputs!D18 -> 283.04869 | F43: =F5*Inputs!E18 -> 333.99745 | G43: =G5*Inputs!F18 -> 384.09707 | H43: Prepaids % revenue
...

Sheet DCF
A1: Palantir DCF Valuation
A3: $mm except per share | B3: 2026E | C3: 2027E | D3: 2028E | E3: 2029E | F3: 2030E | G3: Terminal | H3: Notes
A4: Revenue | B4: ='Forecast Model'!C5 -> 6041.8521 | C4: ='Forecast Model'!D5 -> 7733.5707 | D4: ='Forecast Model'!E5 -> 9434.9562 | E4: ='Forecast Model'!F5 -> 11133.248 | F4: ='Forecast Model'!G5 -> 12803.236
A5: EBIT | B5: ='Forecast Model'!C17 -> 2054.2297 | C5: ='Forecast Model'!D17 -> 2822.7533 | D5: ='Forecast Model'!E17 -> 3632.4582 | E5: ='Forecast Model'!F17 -> 4508.9656 | F5: ='Forecast Model'!G17 -> 5441.3751
A6: Tax rate | B6: ='Forecast Model'!C23 -> 0.03 | C6: ='Forecast Model'!D23 -> 0.05 | D6: ='Forecast Model'!E23 -> 0.08 | E6: ='Forecast Model'!F23 -> 0.1 | F6: ='Forecast Model'!G23 -> 0.12
A7: NOPAT | B7: =B5*(1-B6) -> 1992.6028 | C7: =C5*(1-C6) -> 2681.6156 | D7: =D5*(1-D6) -> 3341.8615 | E7: =E5*(1-E6) -> 4058.069 | F7: =F5*(1-F6) -> 4788.4101
A8: D&A | B8: ='Forecast Model'!C31 -> 36.251113 | C8: ='Forecast Model'!D31 -> 46.401424 | D8: ='Forecast Model'!E31 -> 56.609737 | E8: ='Forecast Model'!F31 -> 66.79949 | F8: ='Forecast Model'!G31 -> 76.819414
A9: Capex | B9: ='Forecast Model'!C35 -> -48.334817 | C9: ='Forecast Model'!D35 -> -61.868566 | D9: ='Forecast Model'!E35 -> -75.47965 | E9: ='Forecast Model'!F35 -> -89.065987 | F9: ='Forecast Model'!G35 -> -102.42588
A10: Change in NWC | B10: =-'Forecast Model'!C33 -> 199.9287 | C10: =-'Forecast Model'!D33 -> 208.35286 | D10: =-'Forecast Model'!E33 -> 224.58077 | E10: =-'Forecast Model'!F33 -> 222.53572 | F10: =-'Forecast Model'!G33 -> 182.05911 | H10: Simplified from forecast working-capital bridge
A11: Unlevered FCF | B11: =B7+B8+B9+B10 -> 2180.4478 | C11: =C7+C8+C9+C10 -> 2874.5014 | D11: =D7+D8+D9+D10 -> 3547.5724 | E11: =E7+E8+E9+E10 -> 4258.3383 | F11: =F7+F8+F9+F10 -> 4944.8628
A12: Discount period | B12: 0.5 | C12: 1.5 | D12: 2.5 | E12: 3.5 | F12: 4.5 | H12: Mid-year convention
A13: WACC | B13: =Inputs!B21 -> 0.095 | C13: =Inputs!B21 -> 0.095 | D13: =Inputs!B21 -> 0.095 | E13: =Inputs!B21 -> 0.095 | F13: =Inputs!B21 -> 0.095 | H13: Assumption
A14: PV factor | B14: =1/(1+B13)^B12 -> 0.95563697 | C14: =1/(1+C13)^C12 -> 0.87272782 | D14: =1/(1+D13)^D12 -> 0.79701171 | E14: =1/(1+E13)^E12 -> 0.72786458 | F14: =1/(1+F13)^F12 -> 0.66471651
A15: PV of FCF | B15: =B11*B14 -> 2083.7165 | C15: =C11*C14 -> 2508.6573 | D15: =D11*D14 -> 2827.4567 | E15: =E11*E14 -> 3099.4936 | F15: =F11*F14 -> 3286.9319
A16: Terminal value | G16: =F11*(1+Inputs!B22)/(Inputs!B21-Inputs!B22) -> 85298.883 | H16: Gordon Growth
A17: PV of terminal value | G17: =G16/(1+Inputs!B21)^4.5 -> 56699.575
A18: Enterprise value | G18: =SUM(B15:F15)+G17 -> 70505.831
A19: Cash & marketable securities | G19: =Inputs!B24 -> 7177.043 | H19: FY2025 actual
A20: Debt | G20: =Inputs!B25 -> 0 | H20: FY2025 actual
A21: Equity value | G21: =G18+G19-G20 -> 77682.874
A22: Diluted shares | G22: =Inputs!B23 -> 2565.197 | H22: FY2025 diluted shares
A23: Implied equity value / share | G23: =G21/G22 -> 30.283395
A27: Sensitivity: Implied Equity Value / Share
A28: WACC \ g | B28: 0.025 | C28: 0.03 | D28: 0.035 | E28: 0.04 | F28: 0.045
A29: 0.085 | B29: =(SUM($B$15:$F$15)+($F$11*(1+B$28)/($A29-B$28))/(1+$A29)^4.5+$G$19-$G$20)/$G$22 -> 30.992465 | C29: =(SUM($B$15:$F$15)+($F$11*(1+C$28)/($A29-C$28))/(1+$A29)^4.5+$G$19-$G$20)/$G$22 -> 33.187723 | D29: =(SUM($B$15:$F$15)+($F$11*(1+D$28)/($A29-D$28))/(1+$A29)^4.5+$G$19-$G$20)/$G$22 -> 35.822032 | E29: =(SUM($B$15:$F$15)+($F$11*(1+E$28)/($A29-E$28))/(1+$A29)^4.5+$G$19-$G$20)/$G$22 -> 39.041743 | F29: =(SUM($B$15:$F$15)+($F$11*(1+F$28)/($A29-F$28))/(1+$A29)^4.5+$G$19-$G$20)/$G$22 -> 43.066382
A30: 0.09 | B30: =(SUM($B$15:$F$15)+($F$11*(1+B$28)/($A30-B$28))/(1+$A30)^4.5+$G$19-$G$20)/$G$22 -> 28.806459 | C30: =(SUM($B$15:$F$15)+($F$11*(1+C$28)/($A30-C$28))/(1+$A30)^4.5+$G$19-$G$20)/$G$22 -> 30.634333 | D30: =(SUM($B$15:$F$15)+($F$11*(1+D$28)/($A30-D$28))/(1+$A30)^4.5+$G$19-$G$20)/$G$22 -> 32.794547 | E30: =(SUM($B$15:$F$15)+($F$11*(1+E$28)/($A30-E$28))/(1+$A30)^4.5+$G$19-$G$20)/$G$22 -> 35.386805 | F30: =(SUM($B$15:$F$15)+($F$11*(1+F$28)/($A30-F$28))/(1+$A30)^4.5+$G$19-$G$20)/$G$22 -> 38.555119
A31: 0.095 | B31: =(SUM($B$15:$F$15)+($F$11*(1+B$28)/($A31-B$28))/(1+$A31)^4.5+$G$19-$G$20)/$G$22 -> 26.942716 | C31: =(SUM($B$15:$F$15)+($F$11*(1+C$28)/($A31-C$28))/(1+$A31)^4.5+$G$19-$G$20)/$G$22 -> 28.484568 | D31: =(SUM($B$15:$F$15)+($F$11*(1+D$28)/($A31-D$28))/(1+$A31)^4.5+$G$19-$G$20)/$G$22 -> 30.283395 | E31: =(SUM($B$15:$F$15)+($F$11*(1+E$28)/($A31-E$28))/(1+$A31)^4.5+$G$19-$G$20)/$G$22 -> 32.409282 | F31: =(SUM($B$15:$F$15)+($F$11*(1+F$28)/($A31-F$28))/(1+$A31)^4.5+$G$19-$G$20)/$G$22 -> 34.960346
A32: 0.1 | B32: =(SUM($B$15:$F$15)+($F$11*(1+B$28)/($A32-B$28))/(1+$A32)^4.5+$G$19-$G$20)/$G$22 -> 25.336509 | C32: =(SUM($B$15:$F$15)+($F$11*(1+C$28)/($A32-C$28))/(1+$A32)^4.5+$G$19-$G$20)/$G$22 -> 26.651642 | D32: =(SUM($B$15:$F$15)+($F$11*(1+D$28)/($A32-D$28))/(1+$A32)^4.5+$G$19-$G$20)/$G$22 -> 28.169104 | E32: =(SUM($B$15:$F$15)+($F$11*(1+E$28)/($A32-E$28))/(1+$A32)^4.5+$G$19-$G$20)/$G$22 -> 29.939476 | F32: =(SUM($B$15:$F$15)+($F$11*(1+F$28)/($A32-F$28))/(1+$A32)^4.5+$G$19-$G$20)/$G$22 -> 32.031734
A33: 0.105 | B33: =(SUM($B$15:$F$15)+($F$11*(1+B$28)/($A33-B$28))/(1+$A33)^4.5+$G$19-$G$20)/$G$22 -> 23.939303 | C33: =(SUM($B$15:$F$15)+($F$11*(1+C$28)/($A33-C$28))/(1+$A33)^4.5+$G$19-$G$20)/$G$22 -> 25.071923 | D33: =(SUM($B$15:$F$15)+($F$11*(1+D$28)/($A33-D$28))/(1+$A33)^4.5+$G$19-$G$20)/$G$22 -> 26.366347 | E33: =(SUM($B$15:$F$15)+($F$11*(1+E$28)/($A33-E$28))/(1+$A33)^4.5+$G$19-$G$20)/$G$22 -> 27.859912 | F33: =(SUM($B$15:$F$15)+($F$11*(1+F$28)/($A33-F$28))/(1+$A33)^4.5+$G$19-$G$20)/$G$22 -> 29.602404

Sheet Segment & SBC
A1: Palantir Segment Revenue, Geography, Contribution, and SBC
A3: Segment / metric | B3: 2023A | C3: 2024A | D3: 2025A | E3: Source
A4: Government revenue | B4: 1222.215 | C4: 1569.605 | D4: 2402.287 | E4: FY2025 10-K segment note
A5: Government contribution | B5: 724.97 | C5: 948.44 | D5: 1576.07 | E5: FY2025 10-K segment note
A6: Government contribution margin | B6: =B5/B4 -> 0.59316078 | C6: =C5/C4 -> 0.60425394 | D6: =D5/D4 -> 0.65607065 | E6: Formula
A7: Commercial revenue | B7: 1002.797 | C7: 1295.902 | D7: 2073.159 | E7: FY2025 10-K segment note
A8: Commercial contribution | B8: 520.585 | C8: 771.508 | D8: 1366.627 | E8: FY2025 10-K segment note
A9: Commercial contribution margin | B9: =B8/B7 -> 0.51913299 | C9: =C8/C7 -> 0.5953444 | D9: =D8/D7 -> 0.65920028 | E9: Formula
A10: Total contribution | B10: 1245.555 | C10: 1719.948 | D10: 2942.697 | E10: FY2025 10-K segment note
A11: Total contribution margin | B11: =B10/(B4+B7) -> 0.55979698 | C11: =C10/(C4+C7) -> 0.60022467 | D11: =D10/(D4+D7) -> 0.65752039 | E11: Formula
A12: United States revenue | B12: 1378.247 | C12: 1900.247 | D12: 3320.043 | E12: FY2025 10-K geography note
A13: United Kingdom revenue | B13: 235.257 | C13: 304.575 | D13: 427.398 | E13: FY2025 10-K geography note
A14: Rest of world revenue | B14: 611.508 | C14: 660.685 | D14: 728.005 | E14: FY2025 10-K geography note
A15: Total revenue | B15: 2225.012 | C15: 2865.507 | D15: 4475.446 | E15: FY2025 10-K geography note
A16: SBC - cost of revenue | B16: 35.995 | C16: 69.065 | D16: 64.555 | E16: FY2025 10-K SBC note
A17: SBC - sales & marketing | B17: 160.645 | C17: 239.121 | D17: 248.732 | E17: FY2025 10-K SBC note
A18: SBC - R&D | B18: 98.064 | C18: 165.065 | D18: 136.839 | E18: FY2025 10-K SBC note
A19: SBC - G&A | B19: 181.199 | C19: 218.387 | D19: 233.907 | E19: FY2025 10-K SBC note
A20: Total SBC | B20: 475.903 | C20: 691.638 | D20: 684.033 | E20: FY2025 10-K SBC note
A21: SBC % revenue | B21: =B20/B15 -> 0.21388784 | C21: =C20/C15 -> 0.24136671 | D21: =D20/D15 -> 0.1528413 | E21: Formula

Sheet Sources
A1: Source Map — Historical Actuals and Model Inputs
A3: Item | B3: Source | C3: URL | D3: Lines / location | E3: Usage
A4: FY2025 10-K PDF | B4: Palantir investor relations / Form 10-K | C4: https://investors.palantir.com/files/2025%20FY%20PLTR%2010-K.pdf | D4: Financial statements pages 84–89; notes pages 98–112 | E4: 2025/2024 balance sheet; 2023–2025 income statement; cash flows; segment/geography/SBC
A5: FY2024 10-K HTML | B5: SEC EDGAR filing | C5: https://www.sec.gov/Archives/edgar/data/1321655/000132165525000022/pltr-20241231.htm | D5: Balance sheet lines 2722–2758 | E5: FY2023 balance sheet actuals
A6: FY2025 operations table | B6: FY2025 10-K PDF | C6: https://investors.palantir.com/files/2025%20FY%20PLTR%2010-K.pdf | D6: p.85 / lines 4161–4183 | E6: Income statement and diluted shares
A7: FY2025 cash flows | B7: FY2025 10-K PDF | C7: https://investors.palantir.com/files/2025%20FY%20PLTR%2010-K.pdf | D7: p.88 / lines 4277–4308 | E7: Cash flow statement
A8: FY2025 balance sheet | B8: FY2025 10-K PDF | C8: https://investors.palantir.com/files/2025%20FY%20PLTR%2010-K.pdf | D8: p.84 / lines 4115–4154 | E8: Balance sheet actuals
A9: Segment / geographic / SBC notes | B9: FY2025 10-K PDF | C9: https://investors.palantir.com/files/2025%20FY%20PLTR%2010-K.pdf | D9: lines 5403–5435 and 5147–5155 | E9: Segment, geography, and SBC tabs

Sheet QA Checks
A1: QA Checks
A3: Check | B3: 2023A | C3: 2024A | D3: 2025A | E3: Forecast / model | F3: Status
A4: Revenue tie-out | B4: ='Historical Financials'!B5-2225.012 -> 0 | C4: ='Historical Financials'!C5-2865.507 -> 0 | D4: ='Historical Financials'!D5-4475.446 -> 0 | F4: =IF(AND(B4=0,C4=0,D4=0),"PASS","CHECK") -> PASS
A5: Operating income tie-out | B5: ='Historical Financials'!B12-119.966 -> 0 | C5: ='Historical Financials'!C12-310.403 -> 0 | D5: ='Historical Financials'!D12-1414.015 -> 0 | F5: =IF(AND(B5=0,C5=0,D5=0),"PASS","CHECK") -> PASS
A6: Net income attr. tie-out | B6: ='Historical Financials'!B19-209.825 -> 0 | C6: ='Historical Financials'!C19-462.19 -> 0 | D6: ='Historical Financials'!D19-1625.033 -> 0 | F6: =IF(AND(B6=0,C6=0,D6=0),"PASS","CHECK") -> PASS
A7: Total assets tie-out | B7: ='Historical Financials'!B30-4522.425 -> 0 | C7: ='Historical Financials'!C30-6340.884 -> 0 | D7: ='Historical Financials'!D30-8900.392 -> 0 | F7: =IF(AND(B7=0,C7=0,D7=0),"PASS","CHECK") -> PASS
A8: Liabilities + equity tie-out | B8: ='Historical Financials'!B49-4522.425 -> 0 | C8: ='Historical Financials'!C49-6340.884 -> 0 | D8: ='Historical Financials'!D49-8900.392 -> 0 | F8: =IF(AND(B8=0,C8=0,D8=0),"PASS","CHECK") -> PASS
A9: CFO tie-out | B9: ='Historical Financials'!B56-712.183 -> 0 | C9: ='Historical Financials'!C56-1153.865 -> 0 | D9: ='Historical Financials'!D56-2134.473 -> 0 | F9: =IF(AND(B9=0,C9=0,D9=0),"PASS","CHECK") -> PASS
A10: Historical balance sheet check | B10: ='Historical Financials'!B30-'Historical Financials'!B49 -> 0 | C10: ='Historical Financials'!C30-'Historical Financials'!C49 -> 0 | D10: ='Historical Financials'!D30-'Historical Financials'!D49 -> 0 | F10: =IF(AND(B10=0,C10=0,D10=0),"PASS","CHECK") -> PASS
A11: Forecast balance check | E11: =ABS('Forecast Model'!C70)+ABS('Forecast Model'!D70)+ABS('Forecast Model'!E70)+ABS('Forecast Model'!F70)+ABS('Forecast Model'!G70) -> 0 | F11: =IF(E11<0.1,"PASS","CHECK") -> PASS
A12: DCF sensitivity built | E12: =IF(DCF!G23>0,"PASS","CHECK") -> PASS | F12: =E12 -> PASS
