Workbook

Sheet Summary
A1: VALUE-ADD MULTIFAMILY — Parkview Apartments, Sacramento, CA (Illustrative Case Study)
A3: Deal Overview
A4: Property Name | C4: Parkview Apartments (Value-Add Case Study)
A5: Market | C5: Sacramento, CA
A6: Units | C6: 48
A7: Year Built | C7: 1985
A8: Purchase Price | C8: 8400000
A9: Price / Unit | C9: =C8/C6 -> 175000
A10: Renovation $ / Unit | C10: 18000
A11: Closing Cost % | C11: 0.015
A12: Loan-to-Cost (LTC) | C12: 0.65
A13: Loan Origination Fee % | C13: 0.01
A15: Sources & Uses
A16: USES
A17: Purchase Price | C17: =C8 -> 8400000
A18: Closing Costs | C18: =C8*C11 -> 126000
A19: Renovation Budget | C19: =C10*C6 -> 864000
A20: Loan Origination Fee | C20: =C24*C13 -> 60216
A21: Total Uses | C21: =SUM(C17:C20) -> 9450216
A23: SOURCES
A24: Senior Loan (LTC x [Price+Reno]) | C24: =C12*(C8+C19) -> 6021600
A25: Total Equity | C25: =C21-C24 -> 3428616
A26: Check (Sources - Uses) | C26: =C24+C25-C21 -> 0
A28: Equity Structure
A29: LP Capital Share | C29: 0.9
A30: GP Capital Share | C30: 0.1
A31: LP Equity | C31: =C25*C29 -> 3085754.4
A32: GP Equity | C32: =C25*C30 -> 342861.6
A34: Returns Summary (5-Year Hold)
A35: Going-in Cap Rate (Yr1 NOI / Price) | C35: =Operations!C42/C8 -> 0.070810514
A36: Stabilized NOI (Year 3) | C36: =Operations!E42 -> 721999.42
A37: Stabilized Yield-on-Cost | C37: =C36/C21 -> 0.076400309
A38: Exit Cap Rate | C38: =CashFlow!B4 -> 0.065
A39: Project Unlevered IRR | C39: =CashFlow!B27 -> 0.11348105
A40: Project Levered IRR | C40: =CashFlow!B28 -> 0.1860821
A41: Project Equity Multiple | C41: =CashFlow!B29 -> 2.174224
A42: LP IRR | C42: =Waterfall!B29 -> 0.1658764
A43: LP Equity Multiple | C43: =Waterfall!B30 -> 2.0025436
A44: GP IRR (with promote) | C44: =Waterfall!B31 -> 0.32340325
A45: GP Equity Multiple | C45: =Waterfall!B32 -> 3.7193473
...

Sheet Operations
A1: OPERATIONS — Value-Add Rent Ramp & 5-Year Operating Statement
A3: Operating Assumptions
A4: In-Place Blended Rent ($/unit/mo) | B4: 1650
A5: Stabilized Rent ($/unit/mo) | B5: 1950
A6: Units (link) | B6: =Summary!C6 -> 48
A7: % Units Renovated - Year 1 | B7: 0.6
A8: % Units Renovated - Year 2 | B8: 1
A9: Market Rent Growth (post-stabilization) | B9: 0.03
A10: Other Income ($/unit/mo) | B10: 45
A11: Vacancy - Year 1 (reno downtime) | B11: 0.1
A12: Vacancy - Year 2 | B12: 0.06
A13: Vacancy - Year 3+ (stabilized) | B13: 0.05
A14: Management Fee (% EGI) | B14: 0.04
A15: Property Tax Rate (% of Price) | B15: 0.012
A16: Property Tax Growth | B16: 0.02
A17: Expense Growth | B17: 0.03
A18: Capital Reserves ($/unit/yr) | B18: 350
... A23: Utilities ($/unit/yr) | B23: 850
A25: 5-Year Operating Statement
C26: Year 1 | D26: Year 2 | E26: Year 3 | F26: Year 4 | G26: Year 5
A27: Blended Rent / Unit / Month | C27: =$B$4*(1-$B$7)+$B$5*$B$7 -> 1830 | D27: =$B$5 -> 1950 | E27: =D27*(1+$B$9) -> 2008.5 | F27: =E27*(1+$B$9) -> 2068.755 | G27: =F27*(1+$B$9) -> 2130.8176
A28: Vacancy Rate | C28: =$B$11 -> 0.1 | D28: =$B$12 -> 0.06 | E28: =$B$13 -> 0.05 | F28: =$B$13 -> 0.05 | G28: =$B$13 -> 0.05
A29: Gross Potential Rent (GPR) | C29: =$B$6*C27*12 -> 1054080 | D29: =$B$6*D27*12 -> 1123200 | E29: =$B$6*E27*12 -> 1156896 | F29: =$B$6*F27*12 -> 1191602.9 | G29: =$B$6*G27*12 -> 1227351
A30: Vacancy & Credit Loss | C30: =-C29*C28 -> -105408 | D30: =-D29*D28 -> -67392 | E30: =-E29*E28 -> -57844.8 | F30: =-F29*F28 -> -59580.144 | G30: =-G29*G28 -> -61367.548
A31: Other Income | C31: =$B$10*$B$6*12 -> 25920 | D31: =C31*(1+$B$9) -> 26697.6 | E31: =D31*(1+$B$9) -> 27498.528 | F31: =E31*(1+$B$9) -> 28323.484 | G31: =F31*(1+$B$9) -> 29173.188
A32: Effective Gross Income (EGI) | C32: =C29+C30+C31 -> 974592 | D32: =D29+D30+D31 -> 1082505.6 | E32: =E29+E30+E31 -> 1126549.7 | F32: =F29+F30+F31 -> 1160346.2 | G32: =G29+G30+G31 -> 1195156.6
A33: Operating Expenses:
A34: Property Taxes | C34: =$B$15*Summary!$C$8 -> 100800 | D34: =C34*(1+$B$16) -> 102816 | E34: =D34*(1+$B$16) -> 104872.32 | F34: =E34*(1+$B$16) -> 106969.77 | G34: =F34*(1+$B$16) -> 109109.16
A35: Insurance | C35: =$B$19*$B$6 -> 43200 | D35: =C35*(1+$B$17) -> 44496 | E35: =D35*(1+$B$17) -> 45830.88 | F35: =E35*(1+$B$17) -> 47205.806 | G35: =F35*(1+$B$17) -> 48621.981
A36: Repairs & Maintenance | C36: =$B$20*$B$6 -> 72000 | D36: =C36*(1+$B$17) -> 74160 | E36: =D36*(1+$B$17) -> 76384.8 | F36: =E36*(1+$B$17) -> 78676.344 | G36: =F36*(1+$B$17) -> 81036.634
A37: Payroll & On-site Mgmt | C37: =$B$21*$B$6 -> 67200 | D37: =C37*(1+$B$17) -> 69216 | E37: =D37*(1+$B$17) -> 71292.48 | F37: =E37*(1+$B$17) -> 73431.254 | G37: =F37*(1+$B$17) -> 75634.192
A38: General & Administrative | C38: =$B$22*$B$6 -> 16800 | D38: =C38*(1+$B$17) -> 17304 | E38: =D38*(1+$B$17) -> 17823.12 | F38: =E38*(1+$B$17) -> 18357.814 | G38: =F38*(1+$B$17) -> 18908.548
A39: Utilities | C39: =$B$23*$B$6 -> 40800 | D39: =C39*(1+$B$17) -> 42024 | E39: =D39*(1+$B$17) -> 43284.72 | F39: =E39*(1+$B$17) -> 44583.262 | G39: =F39*(1+$B$17) -> 45920.759
A40: Management Fee | C40: =$B$14*C32 -> 38983.68 | D40: =$B$14*D32 -> 43300.224 | E40: =$B$14*E32 -> 45061.989 | F40: =$B$14*F32 -> 46413.849 | G40: =$B$14*G32 -> 47806.264
A41: Total Operating Expenses | C41: =SUM(C34:C39)+C40 -> 379783.68 | D41: =SUM(D34:D39)+D40 -> 393316.22 | E41: =SUM(E34:E39)+E40 -> 404550.31 | F41: =SUM(F34:F39)+F40 -> 415638.1 | G41: =SUM(G34:G39)+G40 -> 427037.54
A42: Net Operating Income (NOI) | C42: =C32-C41 -> 594808.32 | D42: =D32-D41 -> 689189.38 | E42: =E32-E41 -> 721999.42 | F42: =F32-F41 -> 744708.12 | G42: =G32-G41 -> 768119.07
A43: Capital Reserves | C43: =$B$18*$B$6 -> 16800 | D43: =C43*(1+$B$17) -> 17304 | E43: =D43*(1+$B$17) -> 17823.12 | F43: =E43*(1+$B$17) -> 18357.814 | G43: =F43*(1+$B$17) -> 18908.548

Sheet Debt
A1: DEBT — Bridge Loan (Interest-Only)
A3: Loan Terms
A4: Loan Amount (link) | B4: =Summary!C24 -> 6021600
A5: Interest Rate (annual, IO) | B5: 0.0625
A6: Loan Type | B6: Interest-Only (Bridge)
A7: Hold Period (years) | B7: 5
A9: 5-Year Debt Service (Interest-Only)
C10: Year 1 | D10: Year 2 | E10: Year 3 | F10: Year 4 | G10: Year 5
A11: Beginning Balance | C11: =$B$4 -> 6021600 | D11: =$B$4 -> 6021600 | E11: =$B$4 -> 6021600 | F11: =$B$4 -> 6021600 | G11: =$B$4 -> 6021600
A12: Debt Service (Interest) | C12: =$B$4*$B$5 -> 376350 | D12: =$B$4*$B$5 -> 376350 | E12: =$B$4*$B$5 -> 376350 | F12: =$B$4*$B$5 -> 376350 | G12: =$B$4*$B$5 -> 376350
A13: Ending Balance | C13: =$B$4 -> 6021600 | D13: =$B$4 -> 6021600 | E13: =$B$4 -> 6021600 | F13: =$B$4 -> 6021600 | G13: =$B$4 -> 6021600
A14: DSCR (NOI / Debt Service) | C14: =Operations!C42/C12 -> 1.5804658 | D14: =Operations!D42/D12 -> 1.8312459 | E14: =Operations!E42/E12 -> 1.9184255 | F14: =Operations!F42/F12 -> 1.9787648 | G14: =Operations!G42/G12 -> 2.04097

Sheet CashFlow
A1: CASH FLOW & RETURNS — Project-Level (Unlevered & Levered)
A3: Exit Assumptions
A4: Exit Cap Rate | B4: 0.065
A5: Selling Costs (%) | B5: 0.02
A6: Hold (years) | B6: =Debt!B7 -> 5
A8: 5-Year Cash Flow
B9: Year 0 | C9: Year 1 | D9: Year 2 | E9: Year 3 | F9: Year 4 | G9: Year 5
A10: Net Operating Income (NOI) | C10: =Operations!C42 -> 594808.32 | D10: =Operations!D42 -> 689189.38 | E10: =Operations!E42 -> 721999.42 | F10: =Operations!F42 -> 744708.12 | G10: =Operations!G42 -> 768119.07
A11: Less: Capital Reserves | C11: =Operations!C43 -> 16800 | D11: =Operations!D43 -> 17304 | E11: =Operations!E43 -> 17823.12 | F11: =Operations!F43 -> 18357.814 | G11: =Operations!G43 -> 18908.548
A12: Unlevered Cash Flow | C12: =C10-C11 -> 578008.32 | D12: =D10-D11 -> 671885.38 | E12: =E10-E11 -> 704176.3 | F12: =F10-F11 -> 726350.31 | G12: =G10-G11 -> 749210.52
A13: Less: Debt Service | C13: =Debt!C12 -> 376350 | D13: =Debt!D12 -> 376350 | E13: =Debt!E12 -> 376350 | F13: =Debt!F12 -> 376350 | G13: =Debt!G12 -> 376350
A14: Levered Cash Flow (pre-sale) | C14: =C12-C13 -> 201658.32 | D14: =D12-D13 -> 295535.38 | E14: =E12-E13 -> 327826.3 | F14: =F12-F13 -> 350000.31 | G14: =G12-G13 -> 372860.52
A16: Reversion (Year 5 Sale)
A17: Forward NOI (Year 6E) | G17: =G10*(1+Operations!$B$9) -> 791162.64
A18: Gross Sale Price | G18: =G17/$B$4 -> 12171733
A19: Less: Selling Costs | G19: =-G18*$B$5 -> -243434.66
A20: Less: Loan Payoff | G20: =-Debt!G13 -> -6021600
A21: Net Sale Proceeds to Equity | G21: =G18+G19+G20 -> 5906698.2
A23: Total Unlevered Cash Flow | B23: =-Summary!$C$21 -> -9450216 | C23: =C12 -> 578008.32 | D23: =D12 -> 671885.38 | E23: =E12 -> 704176.3 | F23: =F12 -> 726350.31 | G23: =G12+G18+G19 -> 12677509
A24: Total Levered Cash Flow (Equity) | B24: =-Summary!$C$25 -> -3428616 | C24: =C14 -> 201658.32 | D24: =D14 -> 295535.38 | E24: =E14 -> 327826.3 | F24: =F14 -> 350000.31 | G24: =G14+G21 -> 6279558.8
A26: Return Metrics
A27: Unlevered IRR | B27: =IRR(B23:G23) -> 0.11348105
A28: Levered IRR | B28: =IRR(B24:G24) -> 0.1860821
A29: Equity Multiple | B29: =SUM(C24:G24)/-B24 -> 2.174224
A30: Avg Cash-on-Cash (operating) | B30: =AVERAGE(C14:F14)/-B24 -> 0.08567745

Sheet Waterfall
A1: EQUITY WATERFALL — LP / GP Distribution (8% Pref, 70/30 Promote)
A3: Waterfall Terms
A4: Preferred Return (cumulative) | B4: 0.08
A5: LP Capital Share | B5: =Summary!C29 -> 0.9
A6: GP Capital Share | B6: =Summary!C30 -> 0.1
A7: Residual Split - LP | B7: 0.7
A8: Residual Split - GP (promote) | B8: 0.3
A9: Total Equity | B9: =Summary!C25 -> 3428616
A11: Distribution Waterfall
B12: Year 0 | C12: Year 1 | D12: Year 2 | E12: Year 3 | F12: Year 4 | G12: Year 5
A13: Distributable Equity Cash Flow | B13: =CashFlow!B24 -> -3428616 | C13: =CashFlow!C24 -> 201658.32 | D13: =CashFlow!D24 -> 295535.38 | E13: =CashFlow!E24 -> 327826.3 | F13: =CashFlow!F24 -> 350000.31 | G13: =CashFlow!G24 -> 6279558.8
A15: 8% Hurdle Account (Return of Capital + Pref)
A16: Beginning Balance | C16: =$B$9 -> 3428616 | D16: =C19 -> 3501247 | E16: =D19 -> 3485811.3 | F16: =E19 -> 3436849.9 | G16: =F19 -> 3361797.6
A17: Accrued at 8% (BOP x 1.08) | C17: =C16*(1+$B$4) -> 3702905.3 | D17: =D16*(1+$B$4) -> 3781346.7 | E17: =E16*(1+$B$4) -> 3764676.2 | F17: =F16*(1+$B$4) -> 3711797.9 | G17: =G16*(1+$B$4) -> 3630741.4
A18: Distribution to Hurdle | C18: =MIN(MAX(C13,0),C17) -> 201658.32 | D18: =MIN(MAX(D13,0),D17) -> 295535.38 | E18: =MIN(MAX(E13,0),E17) -> 327826.3 | F18: =MIN(MAX(F13,0),F17) -> 350000.31 | G18: =MIN(MAX(G13,0),G17) -> 3630741.4
A19: Ending Balance | C19: =C17-C18 -> 3501247 | D19: =D17-D18 -> 3485811.3 | E19: =E17-E18 -> 3436849.9 | F19: =F17-F18 -> 3361797.6 | G19: =G17-G18 -> 0
A20: Residual After Hurdle | C20: =MAX(0,C13-C18) -> 0 | D20: =MAX(0,D13-D18) -> 0 | E20: =MAX(0,E13-E18) -> 0 | F20: =MAX(0,F13-F18) -> 0 | G20: =MAX(0,G13-G18) -> 2648817.3
A22: LP Distribution | C22: =C18*$B$5+C20*$B$7 -> 181492.49 | D22: =D18*$B$5+D20*$B$7 -> 265981.84 | E22: =E18*$B$5+E20*$B$7 -> 295043.67 | F22: =F18*$B$5+F20*$B$7 -> 315000.28 | G22: =G18*$B$5+G20*$B$7 -> 5121839.4
A23: GP Distribution | C23: =C18*$B$6+C20*$B$8 -> 20165.832 | D23: =D18*$B$6+D20*$B$8 -> 29553.538 | E23: =E18*$B$6+E20*$B$8 -> 32782.63 | F23: =F18*$B$6+F20*$B$8 -> 35000.031 | G23: =G18*$B$6+G20*$B$8 -> 1157719.3
A25: LP Cash Flow | B25: =-Summary!$C$31 -> -3085754.4 | C25: =C22 -> 181492.49 | D25: =D22 -> 265981.84 | E25: =E22 -> 295043.67 | F25: =F22 -> 315000.28 | G25: =G22 -> 5121839.4
A26: GP Cash Flow | B26: =-Summary!$C$32 -> -342861.6 | C26: =C23 -> 20165.832 | D26: =D23 -> 29553.538 | E26: =E23 -> 32782.63 | F26: =F23 -> 35000.031 | G26: =G23 -> 1157719.3
A28: Partner Returns
A29: LP IRR | B29: =IRR(B25:G25) -> 0.1658764
A30: LP Equity Multiple | B30: =SUM(C25:G25)/-B25 -> 2.0025436
A31: GP IRR (with promote) | B31: =IRR(B26:G26) -> 0.32340325
A32: GP Equity Multiple | B32: =SUM(C26:G26)/-B26 -> 3.7193473
A33: Total Distributions | B33: =SUM(C13:G13) -> 7454579.1
A34: GP Pro-Rata Share (10%) | B34: =B33*$B$6 -> 745457.91
A35: GP Promote ($ above pro-rata) | B35: =SUM(C26:G26)-B34 -> 529763.46
