Workbook

Sheet Cover
A1: Restaurant Brands International (QSR) — Banker-Final EDGAR-Tied Model
A3: Company | B3: Restaurant Brands International Limited Partnership
A4: Ticker | B4: QSR
A5: Currency / Units | B5: USD $mm except per-unit data
A6: Historical period | B6: FY2023A–FY2025A
A7: Forecast period | B7: FY2026E–FY2030E
A8: Primary source | B8: EDGAR Form 10-K filed February 20, 2026
A9: Modeling standard | B9: Historical hardcodes from SEC filings; forecasts are assumptions/formulas
A10: Prepared for | B10: Ryan Anden Financial Modeling Portfolio
A11: Last updated | B11: 2026-06-24
A12: Status | B12: QSR model built; source map and QA included
A14: Color Convention: Blue = hardcoded historicals / assumptions; Green = linked from other worksheet; Black = formulas. Yellow fill = key assumption cells.
A16: Investment/Model Thesis
A17: QSR is modeled as a franchisor-heavy quick service restaurant platform with meaningful revenue mix complexity from Tim Hortons supply chain sales, company restaurant sales from Restaurant Holdings, franchise/property revenues, advertising funds, and high leverage. Historical actuals are tied to the FY2025 and FY2024 Form 10-Ks; DCF outputs depend on explicit revenue growth, operating margin, tax, capex, and terminal assumptions.

Sheet Historical_Financials
A1: Historical Financials — EDGAR-Tied Actuals ($mm)
A3: Income Statement ($mm) | B3: 2023A | C3: 2024A | D3: 2025A | E3: Source / Note
A4: Supply chain sales | B4: 2679 | C4: 2708 | D4: 2909 | E4: FY2025 10-K; Statements of Operations
A5: Company restaurant sales | B5: 271 | C5: 1592 | D5: 2348 | E5: FY2025 10-K; Statements of Operations
A6: Franchise and property revenues | B6: 2903 | C6: 2919 | D6: 2960 | E6: FY2025 10-K; Statements of Operations
A7: Advertising revenues and other services | B7: 1169 | C7: 1187 | D7: 1217 | E7: FY2025 10-K; Statements of Operations
A8: Total revenues | B8: 7022 | C8: 8406 | D8: 9434 | E8: FY2025 10-K; Statements of Operations
A9: Supply chain cost of sales | B9: 2193 | C9: 2180 | D9: 2363 | E9: FY2025 10-K; Statements of Operations
A10: Company restaurant expenses | B10: 242 | C10: 1328 | D10: 1968 | E10: FY2025 10-K; Statements of Operations
A11: Franchise and property expenses | B11: 512 | C11: 544 | D11: 552 | E11: FY2025 10-K; Statements of Operations
A12: Advertising expenses and other services | B12: 1273 | C12: 1330 | D12: 1358 | E12: FY2025 10-K; Statements of Operations
A13: General and administrative expenses | B13: 704 | C13: 733 | D13: 741 | E13: FY2025 10-K; Statements of Operations
A14: (Income) loss from equity method investments | B14: -8 | C14: -69 | D14: -11 | E14: FY2025 10-K; Statements of Operations
A15: Other operating expenses (income), net | B15: 55 | C15: -59 | D15: 261 | E15: FY2025 10-K; Statements of Operations
... A28: Weighted average Partnership exchangeable units | B28: 139 | C28: 131 | D28: 126 | E28: FY2025 10-K; Statements of Operations
A30: Balance Sheet ($mm) | B30: 2023A | C30: 2024A | D30: 2025A | E30: Source / Note
A31: Cash and cash equivalents | B31: 1139 | C31: 1334 | D31: 1163 | E31: FY2025 10-K for 2024A/2025A; FY2024 10-K for 2023A
A32: Accounts and notes receivable, net | B32: 749 | C32: 698 | D32: 794 | E32: FY2025 10-K for 2024A/2025A; FY2024 10-K for 2023A
A33: Inventories, net | B33: 166 | C33: 142 | D33: 205 | E33: FY2025 10-K for 2024A/2025A; FY2024 10-K for 2023A
A34: Prepaids and other current assets | B34: 119 | C34: 108 | D34: 179 | E34: FY2025 10-K for 2024A/2025A; FY2024 10-K for 2023A
A35: Assets held for sale - discontinued operations | B35: 0 | C35: 0 | D35: 489 | E35: FY2025 10-K for 2024A/2025A; FY2024 10-K for 2023A
A36: Total current assets | B36: 2173 | C36: 2282 | D36: 2830 | E36: FY2025 10-K for 2024A/2025A; FY2024 10-K for 2023A
A37: Property and equipment, net | B37: 1952 | C37: 2236 | D37: 2303 | E37: FY2025 10-K for 2024A/2025A; FY2024 10-K for 2023A
A38: Operating lease assets, net | B38: 1122 | C38: 1852 | D38: 1961 | E38: FY2025 10-K for 2024A/2025A; FY2024 10-K for 2023A
A39: Intangible assets, net | B39: 11107 | C39: 10922 | D39: 11190 | E39: FY2025 10-K for 2024A/2025A; FY2024 10-K for 2023A
A40: Goodwill | B40: 5775 | C40: 5986 | D40: 6306 | E40: FY2025 10-K for 2024A/2025A; FY2024 10-K for 2023A
A41: Other assets, net | B41: 1262 | C41: 1354 | D41: 1025 | E41: FY2025 10-K for 2024A/2025A; FY2024 10-K for 2023A
A42: Total assets | B42: 23391 | C42: 24632 | D42: 25615 | E42: FY2025 10-K for 2024A/2025A; FY2024 10-K for 2023A
... A61: Total liabilities and equity | B61: 23391 | C61: 24632 | D61: 25615 | E61: FY2025 10-K for 2024A/2025A; FY2024 10-K for 2023A
A65: Cash Flow Statement ($mm) | B65: 2023A | C65: 2024A | D65: 2025A | E65: Source / Note
A66: Net income | B66: 1718 | C66: 1445 | D66: 1075 | E66: FY2025 10-K; Statements of Cash Flows
A67: Net loss from discontinued operations | B67: 0 | C67: 0 | D67: 126 | E67: FY2025 10-K; Statements of Cash Flows
A68: Net income from continuing operations | B68: 1718 | C68: 1445 | D68: 1201 | E68: FY2025 10-K; Statements of Cash Flows
A69: Depreciation and amortization | B69: 191 | C69: 264 | D69: 301 | E69: FY2025 10-K; Statements of Cash Flows
A70: Non-cash loss on early extinguishment of debt | B70: 5 | C70: 23 | D70: 2 | E70: FY2025 10-K; Statements of Cash Flows
A71: Amortization of deferred financing costs and debt issuance discount | B71: 27 | C71: 25 | D71: 25 | E71: FY2025 10-K; Statements of Cash Flows
A72: (Income) loss from equity method investments | B72: -8 | C72: -69 | D72: -11 | E72: FY2025 10-K; Statements of Cash Flows
A73: Loss (gain) on remeasurement of foreign denominated transactions | B73: 20 | C73: -71 | D73: 209 | E73: FY2025 10-K; Statements of Cash Flows
A74: Net (gains) losses on derivatives | B74: -151 | C74: -191 | D74: -198 | E74: FY2025 10-K; Statements of Cash Flows
A75: Share-based compensation and non-cash incentive compensation expense | B75: 194 | C75: 172 | D75: 151 | E75: FY2025 10-K; Statements of Cash Flows
...

Sheet Segment_Detail
A1: Segment Detail — QSR Revenue Mix and Operating Drivers ($mm except restaurant count)
A3: 2025 Segment | B3: System-wide Sales | C3: Revenue | D3: Adjusted Operating Income | E3: System Restaurant Count
A4: TH | B4: 7573 | C4: 4247 | D4: 1077 | E4: 4586
A5: BK | B5: 11578 | C5: 1514 | D5: 468 | E5: 7025
A6: PLK | B6: 6076 | C6: 800 | D6: 250 | E6: 3578
A7: FHS | B7: 1337 | C7: 232 | D7: 56 | E7: 1449
A8: INTL | B8: 20199 | C8: 998 | D8: 690 | E8: 16403
A9: RH | C9: 1840 | D9: 44 | E9: 1087
A10: Eliminations | C10: -197
A11: Total | B11: 46763 | C11: 9434 | D11: 2584 | E11: 34128
A13: 2024 Segment | B13: System-wide Sales | C13: Revenue | D13: Adjusted Operating Income | E13: System Restaurant Count
A14: TH | B14: 7479 | C14: 4040 | D14: 1043 | E14: 4539
A15: BK | B15: 11484 | C15: 1450 | D15: 410 | E15: 7082
A16: PLK | B16: 6124 | C16: 768 | D16: 243 | E16: 3520
A17: FHS | B17: 1233 | C17: 214 | D17: 48 | E17: 1345
A18: INTL | B18: 18156 | C18: 935 | D18: 614 | E18: 15639
A19: RH | C19: 1116 | D19: 44 | E19: 1036
A20: Eliminations | C20: -117
A21: Total | B21: 44476 | C21: 8406 | D21: 2402 | E21: 33161
A23: Notes: RH system-wide sales is not presented in the same way as franchisor brand system-wide sales in the model; total system-wide sales shown here sums disclosed brand-level rows where available. Segment revenue reconciles to consolidated revenue after eliminations.

Sheet Assumptions
A1: Forecast Assumptions — QSR
A3: Assumption | B3: 2026E | C3: 2027E | D3: 2028E | E3: 2029E | F3: 2030E | G3: Rationale | H3: Status
A4: Revenue growth | B4: 0.045 | C4: 0.04 | D4: 0.038 | E4: 0.035 | F4: 0.033 | G4: Moderating growth from system-wide sales, franchise/property revenue, and RH normalization | H4: Assumption
A5: Operating margin | B5: 0.238 | C5: 0.242 | D5: 0.246 | E5: 0.25 | F5: 0.252 | G5: Gradual margin recovery from 2025 after FX/transaction noise | H5: Assumption
A6: Cash tax rate | B6: 0.24 | C6: 0.24 | D6: 0.24 | E6: 0.24 | F6: 0.24 | G6: Normalized long-run cash tax rate; 2025 effective rate was 28.7% | H6: Assumption
A7: D&A as % of revenue | B7: 0.032 | C7: 0.031 | D7: 0.03 | E7: 0.03 | F7: 0.029 | G7: Historical D&A / revenue with modest operating leverage | H7: Assumption
A8: Capex as % of revenue | B8: 0.03 | C8: 0.03 | D8: 0.03 | E8: 0.029 | F8: 0.029 | G8: Capex intensity based on recent capex; includes company restaurant base | H8: Assumption
A9: NWC investment as % of revenue growth | B9: 0.07 | C9: 0.07 | D9: 0.07 | E9: 0.07 | F9: 0.07 | G9: Simplified working-capital investment on incremental revenue | H9: Assumption
A10: WACC | B10: 0.085 | C10: 0.085 | D10: 0.085 | E10: 0.085 | F10: 0.085 | G10: DCF discount rate assumption | H10: Assumption
A11: Terminal growth | B11: 0.025 | C11: 0.025 | D11: 0.025 | E11: 0.025 | F11: 0.025 | G11: Long-run mature franchisor growth assumption | H11: Assumption

Sheet Forecast_Model
A1: Forecast Model — Formula Driven ($mm)
A3: Metric | B3: 2025A | C3: 2026E | D3: 2027E | E3: 2028E | F3: 2029E | G3: 2030E | H3: Source / Linkage
A4: Revenue | B4: =Historical_Financials!D8 -> 9434 | C4: =B4*(1+Assumptions!B4) -> 9858.53 | D4: =C4*(1+Assumptions!C4) -> 10252.871 | E4: =D4*(1+Assumptions!D4) -> 10642.48 | F4: =E4*(1+Assumptions!E4) -> 11014.967 | G4: =F4*(1+Assumptions!F4) -> 11378.461 | H4: 2025A from 10-K; forecast growth assumptions
A5: Revenue growth | B5: =B4/Historical_Financials!C8-1 -> 0.1222936 | C5: =C4/B4-1 -> 0.045 | D5: =D4/C4-1 -> 0.04 | E5: =E4/D4-1 -> 0.038 | F5: =F4/E4-1 -> 0.035 | G5: =G4/F4-1 -> 0.033 | H5: Formula
A6: Operating income | B6: =Historical_Financials!D17 -> 2202 | C6: =C4*Assumptions!B5 -> 2346.3301 | D6: =D4*Assumptions!C5 -> 2481.1948 | E6: =E4*Assumptions!D5 -> 2618.0502 | F6: =F4*Assumptions!E5 -> 2753.7418 | G6: =G4*Assumptions!F5 -> 2867.3722 | H6: 2025A from 10-K; forecast margin assumptions
A7: Operating margin | B7: =B6/B4 -> 0.23341107 | C7: =C6/C4 -> 0.238 | D7: =D6/D4 -> 0.242 | E7: =E6/E4 -> 0.246 | F7: =F6/F4 -> 0.25 | G7: =G6/G4 -> 0.252 | H7: Formula
A8: Tax expense | B8: =Historical_Financials!D21 -> 483 | C8: =C6*Assumptions!B6 -> 563.11923 | D8: =D6*Assumptions!C6 -> 595.48676 | E8: =E6*Assumptions!D6 -> 628.33204 | F8: =F6*Assumptions!E6 -> 660.89803 | G8: =G6*Assumptions!F6 -> 688.16932 | H8: Cash tax assumption
A9: NOPAT | B9: =B6-B8 -> 1719 | C9: =C6-C8 -> 1783.2109 | D9: =D6-D8 -> 1885.7081 | E9: =E6-E8 -> 1989.7181 | F9: =F6-F8 -> 2092.8438 | G9: =G6-G8 -> 2179.2029 | H9: Formula
A10: D&A | B10: =Historical_Financials!D69 -> 301 | C10: =C4*Assumptions!B7 -> 315.47296 | D10: =D4*Assumptions!C7 -> 317.83901 | E10: =E4*Assumptions!D7 -> 319.27441 | F10: =F4*Assumptions!E7 -> 330.44901 | G10: =G4*Assumptions!F7 -> 329.97537 | H10: Forecast % of revenue
A11: Capex | B11: =-Historical_Financials!D85 -> 265 | C11: =C4*Assumptions!B8 -> 295.7559 | D11: =D4*Assumptions!C8 -> 307.58614 | E11: =E4*Assumptions!D8 -> 319.27441 | F11: =F4*Assumptions!E8 -> 319.43405 | G11: =G4*Assumptions!F8 -> 329.97537 | H11: Forecast % of revenue
A12: Change in NWC | B12: =-(Historical_Financials!D78+Historical_Financials!D79+Historical_Financials!D80+Historical_Financials!D81) -> 74 | C12: =-(C4-B4)*Assumptions!B9 -> -29.7171 | D12: =-(D4-C4)*Assumptions!C9 -> -27.603884 | E12: =-(E4-D4)*Assumptions!D9 -> -27.272637 | F12: =-(F4-E4)*Assumptions!E9 -> -26.074077 | G12: =-(G4-F4)*Assumptions!F9 -> -25.444574 | H12: Simplified NWC investment on incremental revenue
A13: Unlevered FCF | B13: =B9+B10-B11+B12 -> 1829 | C13: =C9+C10-C11+C12 -> 1773.2109 | D13: =D9+D10-D11+D12 -> 1868.3571 | E13: =E9+E10-E11+E12 -> 1962.4455 | F13: =F9+F10-F11+F12 -> 2077.7846 | G13: =G9+G10-G11+G12 -> 2153.7583 | H13: Formula
A14: Ending cash | B14: =Historical_Financials!D104 -> 1163 | C14: =B14+C13 -> 2936.2109 | D14: =C14+D13 -> 4804.5679 | E14: =D14+E13 -> 6767.0134 | F14: =E14+F13 -> 8844.798 | G14: =F14+G13 -> 10998.556 | H14: Simple cash bridge from FCF
A15: Debt + finance leases | B15: =Historical_Financials!D46+Historical_Financials!D49+Historical_Financials!D50 -> 13579 | C15: =B15 -> 13579 | D15: =C15 -> 13579 | E15: =D15 -> 13579 | F15: =E15 -> 13579 | G15: =F15 -> 13579 | H15: Held flat for forecast simplification
A16: Forecast balancing item / other net assets | B16: =0 -> 0 | C16: =C15-C14 -> 10642.789 | D16: =D15-D14 -> 8774.4321 | E16: =E15-E14 -> 6811.9866 | F16: =F15-F14 -> 4734.202 | G16: =G15-G14 -> 2580.4437 | H16: Explicitly labeled forecast balancing item only
A17: Balance check | B17: =0 -> 0 | C17: =C14+C16-C15 -> 0 | D17: =D14+D16-D15 -> 0 | E17: =E14+E16-E15 -> 0 | F17: =F14+F16-F15 -> 0 | G17: =G14+G16-G15 -> 0 | H17: Should equal zero

Sheet DCF
A1: DCF Valuation — QSR ($mm except per-unit values)
A3: Metric | B3: 2026E | C3: 2027E | D3: 2028E | E3: 2029E | F3: 2030E | G3: Source / Formula
A4: Unlevered FCF | B4: =Forecast_Model!C13 -> 1773.2109 | C4: =Forecast_Model!D13 -> 1868.3571 | D4: =Forecast_Model!E13 -> 1962.4455 | E4: =Forecast_Model!F13 -> 2077.7846 | F4: =Forecast_Model!G13 -> 2153.7583 | G4: From Forecast_Model
A5: Discount period | B5: 0.5 | C5: 1.5 | D5: 2.5 | E5: 3.5 | F5: 4.5 | G5: Mid-year convention
A6: Discount factor | B6: =1/(1+Assumptions!B10)^B5 -> 0.96003072 | C6: =1/(1+Assumptions!B10)^C5 -> 0.88482094 | D6: =1/(1+Assumptions!B10)^D5 -> 0.81550317 | E6: =1/(1+Assumptions!B10)^E5 -> 0.75161583 | F6: =1/(1+Assumptions!B10)^F5 -> 0.69273348 | G6: Formula
A7: PV of FCF | B7: =B4*B6 -> 1702.3369 | C7: =C4*C6 -> 1653.1615 | D7: =D4*D6 -> 1600.3805 | E7: =E4*E6 -> 1561.6958 | F7: =F4*F6 -> 1491.9805 | G7: Formula
A9: Valuation Summary | B9: Value | C9: Formula / Source
A10: PV of explicit FCF | B10: =SUM(B7:F7) -> 8009.5552 | C10: Sum of PV of FCF
A11: Terminal FCF | B11: =F4*(1+Assumptions!B11) -> 2207.6022 | C11: 2030E FCF grown by terminal growth
A12: Terminal value | B12: =B11/(Assumptions!B10-Assumptions!B11) -> 36793.371 | C12: Gordon Growth TV
A13: PV of terminal value | B13: =B12*F6 -> 25488 | C13: Discounted terminal value
A14: Enterprise value | B14: =B10+B13 -> 33497.555 | C14: PV of FCF + PV of TV
A15: Less: debt + finance leases | B15: =Forecast_Model!B15 -> 13579 | C15: 2025A debt and finance leases
A16: Add: cash | B16: =Forecast_Model!B14 -> 1163 | C16: 2025A cash and cash equivalents
A17: Equity value | B17: =B14-B15+B16 -> 21081.555 | C17: EV - debt + cash
A18: Diluted units outstanding | B18: =Historical_Financials!D27+Historical_Financials!D28 -> 336 | C18: Class A + exchangeable WA units
A19: Implied value per unit | B19: =B17/B18 -> 62.742723 | C19: Equity value / diluted units
A22: WACC / Terminal Growth Sensitivity — Implied Value Per Unit
A23: WACC \ g | B23: 1.5% | C23: 2.0% | D23: 2.5% | E23: 3.0% | F23: 3.5% | G23: 4.0%
A24: 0.075 | B24: =($B$10+($B$11/(0.075-0.015))*$F$6-$B$15+$B$16)/$B$18 -> 62.742723 | C24: =($B$10+($B$11/(0.075-0.02))*$F$6-$B$15+$B$16)/$B$18 -> 69.638827 | D24: =($B$10+($B$11/(0.075-0.025))*$F$6-$B$15+$B$16)/$B$18 -> 77.914151 | E24: =($B$10+($B$11/(0.075-0.03))*$F$6-$B$15+$B$16)/$B$18 -> 88.028437 | F24: =($B$10+($B$11/(0.075-0.035))*$F$6-$B$15+$B$16)/$B$18 -> 100.67129 | G24: =($B$10+($B$11/(0.075-0.04))*$F$6-$B$15+$B$16)/$B$18 -> 116.9264
A25: 0.08 | B25: =($B$10+($B$11/(0.08-0.015))*$F$6-$B$15+$B$16)/$B$18 -> 56.907558 | C25: =($B$10+($B$11/(0.08-0.02))*$F$6-$B$15+$B$16)/$B$18 -> 62.742723 | D25: =($B$10+($B$11/(0.08-0.025))*$F$6-$B$15+$B$16)/$B$18 -> 69.638827 | E25: =($B$10+($B$11/(0.08-0.03))*$F$6-$B$15+$B$16)/$B$18 -> 77.914151 | F25: =($B$10+($B$11/(0.08-0.035))*$F$6-$B$15+$B$16)/$B$18 -> 88.028437 | G25: =($B$10+($B$11/(0.08-0.04))*$F$6-$B$15+$B$16)/$B$18 -> 100.67129
A26: 0.085 | B26: =($B$10+($B$11/(0.085-0.015))*$F$6-$B$15+$B$16)/$B$18 -> 51.905988 | C26: =($B$10+($B$11/(0.085-0.02))*$F$6-$B$15+$B$16)/$B$18 -> 56.907558 | D26: =($B$10+($B$11/(0.085-0.025))*$F$6-$B$15+$B$16)/$B$18 -> 62.742723 | E26: =($B$10+($B$11/(0.085-0.03))*$F$6-$B$15+$B$16)/$B$18 -> 69.638827 | F26: =($B$10+($B$11/(0.085-0.035))*$F$6-$B$15+$B$16)/$B$18 -> 77.914151 | G26: =($B$10+($B$11/(0.085-0.04))*$F$6-$B$15+$B$16)/$B$18 -> 88.028437
A27: 0.09 | B27: =($B$10+($B$11/(0.09-0.015))*$F$6-$B$15+$B$16)/$B$18 -> 47.571294 | C27: =($B$10+($B$11/(0.09-0.02))*$F$6-$B$15+$B$16)/$B$18 -> 51.905988 | D27: =($B$10+($B$11/(0.09-0.025))*$F$6-$B$15+$B$16)/$B$18 -> 56.907558 | E27: =($B$10+($B$11/(0.09-0.03))*$F$6-$B$15+$B$16)/$B$18 -> 62.742723 | F27: =($B$10+($B$11/(0.09-0.035))*$F$6-$B$15+$B$16)/$B$18 -> 69.638827 | G27: =($B$10+($B$11/(0.09-0.04))*$F$6-$B$15+$B$16)/$B$18 -> 77.914151
A28: 0.095 | B28: =($B$10+($B$11/(0.095-0.015))*$F$6-$B$15+$B$16)/$B$18 -> 43.778437 | C28: =($B$10+($B$11/(0.095-0.02))*$F$6-$B$15+$B$16)/$B$18 -> 47.571294 | D28: =($B$10+($B$11/(0.095-0.025))*$F$6-$B$15+$B$16)/$B$18 -> 51.905988 | E28: =($B$10+($B$11/(0.095-0.03))*$F$6-$B$15+$B$16)/$B$18 -> 56.907558 | F28: =($B$10+($B$11/(0.095-0.035))*$F$6-$B$15+$B$16)/$B$18 -> 62.742723 | G28: =($B$10+($B$11/(0.095-0.04))*$F$6-$B$15+$B$16)/$B$18 -> 69.638827

Sheet Sources
A1: Source Map
A3: Source | B3: Filing / page | C3: Used for | D3: URL | E3: Notes
A4: RBI FY2025 Form 10-K | B4: Consolidated Statements of Operations | C4: 2023A–2025A income statement actuals | D4: https://www.sec.gov/Archives/edgar/data/1618755/000161875526000009/qsr-20251231.htm | E4: Lines 1863–1905
A5: RBI FY2025 Form 10-K | B5: Consolidated Balance Sheets | C5: 2024A–2025A balance sheet actuals | D5: https://www.sec.gov/Archives/edgar/data/1618755/000161875526000009/qsr-20251231.htm | E5: Lines 1797–1849
A6: RBI FY2024 Form 10-K | B6: Consolidated Balance Sheets | C6: 2023A balance sheet actuals | D6: https://www.sec.gov/Archives/edgar/data/1618755/000161875525000010/qsr-20241231.htm | E6: Lines 1895–1943 and 3591–3632
A7: RBI FY2025 Form 10-K | B7: Consolidated Statements of Cash Flows | C7: 2023A–2025A cash flow actuals | D7: https://www.sec.gov/Archives/edgar/data/1618755/000161875526000009/qsr-20251231.htm | E7: Lines 2011–2061
A8: RBI FY2025 Form 10-K | B8: Segment Results / Revenue Recognition | C8: 2024A–2025A segment and revenue mix detail | D8: https://www.sec.gov/Archives/edgar/data/1618755/000161875526000009/qsr-20251231.htm | E8: Lines 1113–1339 and 2498–2519

Sheet QA_Checks
A1: QA Checks
A3: Check | B3: 2023A | C3: 2024A | D3: 2025A | E3: Status
A4: Revenue tie-out | B4: =Historical_Financials!B8-7022 -> 0 | C4: =Historical_Financials!C8-8406 -> 0 | D4: =Historical_Financials!D8-9434 -> 0 | E4: =IF(SUM(ABS(B4),ABS(C4),ABS(D4))=0,"PASS","FAIL") -> PASS
A5: Operating income tie-out | B5: =Historical_Financials!B17-2051 -> 0 | C5: =Historical_Financials!C17-2419 -> 0 | D5: =Historical_Financials!D17-2202 -> 0 | E5: =IF(SUM(ABS(B5),ABS(C5),ABS(D5))=0,"PASS","FAIL") -> PASS
A6: Net income attributable tie-out | B6: =Historical_Financials!B26-1715 -> 0 | C6: =Historical_Financials!C26-1442 -> 0 | D6: =Historical_Financials!D26-1074 -> 0 | E6: =IF(SUM(ABS(B6),ABS(C6),ABS(D6))=0,"PASS","FAIL") -> PASS
A7: Balance sheet actual check | B7: =Historical_Financials!B42-Historical_Financials!B61 -> 0 | C7: =Historical_Financials!C42-Historical_Financials!C61 -> 0 | D7: =Historical_Financials!D42-Historical_Financials!D61 -> 0 | E7: =IF(SUM(ABS(B7),ABS(C7),ABS(D7))=0,"PASS","FAIL") -> PASS
A8: Cash flow ending cash tie-out | B8: =Historical_Financials!B104-1139 -> 0 | C8: =Historical_Financials!C104-1334 -> 0 | D8: =Historical_Financials!D104-1163 -> 0 | E8: =IF(SUM(ABS(B8),ABS(C8),ABS(D8))=0,"PASS","FAIL") -> PASS
A9: Forecast balance check | D9: =SUM(ABS(Forecast_Model!C17),ABS(Forecast_Model!D17),ABS(Forecast_Model!E17),ABS(Forecast_Model!F17),ABS(Forecast_Model!G17)) -> 0 | E9: =IF(D9=0,"PASS","FAIL") -> PASS
A10: Formula error scan | E10: No formula errors in key build ranges at export
A12: Modeling note
