Workbook

Sheet Cover
A1: Salesforce, Inc. (CRM) — Banker-Style EDGAR-Tied 3-Statement + DCF Model
A3: Company | B3: Salesforce, Inc.
A4: Ticker | B4: CRM
A5: Fiscal Year End | B5: January 31
A6: Units | B6: $ in millions, except per-share data
A7: Historical Source | B7: FY2026 Form 10-K filed March 2, 2026; FY2025 Form 10-K for FY2024 balance sheet
A8: Model Standard | B8: Historical actuals hardcoded from EDGAR; forecasts formula-driven assumptions
A9: Color Convention | B9: Blue = historical hardcodes / user assumptions; Black = formulas; Green = workbook links
A10: Forecast Period | B10: FY2027E–FY2031E
A11: Last Updated | B11: 2026-06-24
A12: Prepared For | B12: Ryan Anden financial modeling portfolio
A14: Fix status
A15: Formula scan | B15: No formula-error strings found after patch.

Sheet Historical Actuals
A1: Historical Actuals — Salesforce, Inc. ($mm except per-share data)
A3: Line Item | B3: FY2024A | C3: FY2025A | D3: FY2026A | E3: Source
A4: Income Statement
A5: Subscription and support revenue | B5: 32537 | C5: 35679 | D5: 39388 | E5: CRM FY2026 10-K
A6: Professional services and other revenue | B6: 2320 | C6: 2216 | D6: 2137 | E6: CRM FY2026 10-K
A7: Total revenue | B7: 34857 | C7: 37895 | D7: 41525 | E7: CRM FY2026 10-K
A8: Subscription and support cost of revenue | B8: 6177 | C8: 6198 | D8: 6796 | E8: CRM FY2026 10-K
A9: Professional services and other cost of revenue | B9: 2364 | C9: 2445 | D9: 2474 | E9: CRM FY2026 10-K
A10: Total cost of revenue | B10: 8541 | C10: 8643 | D10: 9270 | E10: CRM FY2026 10-K
A11: Gross profit | B11: 26316 | C11: 29252 | D11: 32255 | E11: CRM FY2026 10-K
A12: Research and development | B12: 4906 | C12: 5493 | D12: 5993 | E12: CRM FY2026 10-K
A13: Sales and marketing | B13: 12877 | C13: 13257 | D13: 14345 | E13: CRM FY2026 10-K
A14: General and administrative | B14: 2534 | C14: 2836 | D14: 3000 | E14: CRM FY2026 10-K
A15: Restructuring | B15: 988 | C15: 461 | D15: 586 | E15: CRM FY2026 10-K
A16: Total operating expenses | B16: 21305 | C16: 22047 | D16: 23924 | E16: CRM FY2026 10-K
... A23: Diluted shares | B23: 984 | C23: 974 | D23: 956 | E23: CRM FY2026 10-K
A24: Balance Sheet
A25: Cash and cash equivalents | B25: 8472 | C25: 8848 | D25: 7327 | E25: CRM FY2025/FY2026 10-K
A26: Marketable securities | B26: 5722 | C26: 5184 | D26: 2238 | E26: CRM FY2025/FY2026 10-K
A27: Accounts receivable, net | B27: 11414 | C27: 11945 | D27: 14339 | E27: CRM FY2025/FY2026 10-K
A28: Costs capitalized to obtain revenue contracts, current | B28: 1905 | C28: 1971 | D28: 2075 | E28: CRM FY2025/FY2026 10-K
A29: Prepaid expenses and other current assets | B29: 1561 | C29: 1779 | D29: 2243 | E29: CRM FY2025/FY2026 10-K
A30: Total current assets | B30: 29074 | C30: 29727 | D30: 28222 | E30: CRM FY2025/FY2026 10-K
A31: Property and equipment, net | B31: 3689 | C31: 3236 | D31: 3120 | E31: CRM FY2025/FY2026 10-K
A32: Operating lease right-of-use assets, net | B32: 2366 | C32: 2157 | D32: 2003 | E32: CRM FY2025/FY2026 10-K
A33: Noncurrent costs capitalized to obtain revenue contracts | B33: 2515 | C33: 2475 | D33: 2985 | E33: CRM FY2025/FY2026 10-K
A34: Strategic investments | B34: 4848 | C34: 4852 | D34: 7591 | E34: CRM FY2025/FY2026 10-K
A35: Goodwill | B35: 48620 | C35: 51283 | D35: 57941 | E35: CRM FY2025/FY2026 10-K
A36: Intangible assets, net | B36: 5278 | C36: 4428 | D36: 6815 | E36: CRM FY2025/FY2026 10-K
... A49: Total liabilities and stockholders' equity | B49: 99823 | C49: 102928 | D49: 112305 | E49: CRM FY2025/FY2026 10-K
A50: Cash Flow Statement
A51: Net income | B51: 4136 | C51: 6197 | D51: 7457 | E51: CRM FY2026 10-K
A52: Depreciation and amortization | B52: 3959 | C52: 3477 | D52: 3631 | E52: CRM FY2026 10-K
A53: Amortization of costs capitalized to obtain revenue contracts | B53: 1925 | C53: 2095 | D53: 2197 | E53: CRM FY2026 10-K
A54: Stock-based compensation expense | B54: 2787 | C54: 3183 | D54: 3509 | E54: CRM FY2026 10-K
A55: Gains (losses) on strategic investments, net | B55: 277 | C55: 121 | D55: -1017 | E55: CRM FY2026 10-K
A56: Change in accounts receivable | B56: -659 | C56: -490 | D56: -2160 | E56: CRM FY2026 10-K
A57: Change in costs capitalized to obtain revenue contracts | B57: -1872 | C57: -2121 | D57: -2811 | E57: CRM FY2026 10-K
A58: Change in prepaid/other assets | B58: -843 | C58: -1495 | D58: 819 | E58: CRM FY2026 10-K
A59: Change in accounts payable/accrued/other liabilities | B59: -478 | C59: 1089 | D59: 1014 | E59: CRM FY2026 10-K
...

Sheet Inputs
A1: Inputs & Forecast Assumptions — Salesforce, Inc.
A3: Assumption | B3: FY2027E | C3: FY2028E | D3: FY2029E | E3: FY2030E | F3: FY2031E | G3: Notes
A4: Revenue growth | B4: 0.105 | C4: 0.095 | D4: 0.085 | E4: 0.075 | F4: 0.065 | G4: User-changeable forecast assumption
A5: Gross margin | B5: 0.78 | C5: 0.785 | D5: 0.79 | E5: 0.795 | F5: 0.8 | G5: Formula assumption based on SaaS margin expansion
A6: R&D as % revenue | B6: 0.142 | C6: 0.141 | D6: 0.14 | E6: 0.139 | F6: 0.138 | G6: Forecast assumption
A7: Sales & marketing as % revenue | B7: 0.335 | C7: 0.328 | D7: 0.322 | E7: 0.316 | F7: 0.31 | G7: Forecast assumption
A8: G&A as % revenue | B8: 0.071 | C8: 0.07 | D8: 0.069 | E8: 0.068 | F8: 0.067 | G8: Forecast assumption
A9: Restructuring as % revenue | B9: 0.01 | C9: 0.006 | D9: 0.004 | E9: 0.003 | F9: 0.002 | G9: Forecast assumption
A10: Tax rate | B10: 0.225 | C10: 0.225 | D10: 0.225 | E10: 0.225 | F10: 0.225 | G10: DCF tax assumption
A11: D&A as % revenue | B11: 0.085 | C11: 0.082 | D11: 0.08 | E11: 0.078 | F11: 0.076 | G11: Forecast assumption
A12: SBC as % revenue | B12: 0.08 | C12: 0.076 | D12: 0.072 | E12: 0.068 | F12: 0.064 | G12: Forecast assumption
A13: Capex as % revenue | B13: 0.015 | C13: 0.015 | D13: 0.015 | E13: 0.015 | F13: 0.015 | G13: Forecast assumption
A14: Change in NWC as % revenue | B14: -0.01 | C14: -0.008 | D14: -0.006 | E14: -0.004 | F14: -0.003 | G14: Negative = source of cash
A15: WACC | B15: 0.085 | G15: DCF assumption
A16: Terminal growth | B16: 0.03 | G16: DCF assumption
A17: Diluted shares | B17: 930 | G17: Assumption based on FY2026 diluted shares less buybacks
A18: Current share price | B18: 170 | G18: User-changeable market input; update before publishing

Sheet Operating Model
A1: Operating Model — Salesforce, Inc. ($mm except per-share data)
A3: Line Item | B3: FY2024A | C3: FY2025A | D3: FY2026A | E3: FY2027E | F3: FY2028E | G3: FY2029E | H3: FY2030E | I3: FY2031E
A4: Income Statement
A5: Subscription and support revenue | B5: 32537 | C5: 35679 | D5: 39388 | E5: =D5*(1+Inputs!B4)*95% -> 41347.553 | F5: =E5*(1+Inputs!C4)*95.2% -> 43102.343 | G5: =F5*(1+Inputs!D4)*95.4% -> 44614.804 | H5: =G5*(1+Inputs!E4)*95.6% -> 45850.634 | I5: =H5*(1+Inputs!F4)*95.8% -> 46780.027
A6: Professional services and other revenue | B6: 2320 | C6: 2216 | D6: 2137 | E6: =D6*(1+Inputs!B4)*105% -> 2479.4542 | F6: =E6*(1+Inputs!C4)*104.8% -> 2845.3225 | G6: =F6*(1+Inputs!D4)*104.6% -> 3229.185 | H6: =G6*(1+Inputs!E4)*104.4% -> 3624.1143 | I6: =H6*(1+Inputs!F4)*104.2% -> 4021.7884
A7: Total revenue | B7: 34857 | C7: 37895 | D7: 41525 | E7: =SUM(E5:E6) -> 43827.007 | F7: =SUM(F5:F6) -> 45947.666 | G7: =SUM(G5:G6) -> 47843.989 | H7: =SUM(H5:H6) -> 49474.749 | I7: =SUM(I5:I6) -> 50801.815
A8: Revenue growth | C8: =C7/B7-1 -> 0.087156095 | D8: =D7/C7-1 -> 0.095791001 | E8: =E7/D7-1 -> 0.055436659 | F8: =F7/E7-1 -> 0.048387023 | G8: =G7/F7-1 -> 0.041271382 | H8: =H7/G7-1 -> 0.034084938 | I8: =I7/H7-1 -> 0.026823106
A9: Total cost of revenue | B9: 8541 | C9: 8643 | D9: 9270 | E9: =E7*(1-Inputs!B5) -> 9641.9416 | F9: =F7*(1-Inputs!C5) -> 9878.7481 | G9: =G7*(1-Inputs!D5) -> 10047.238 | H9: =H7*(1-Inputs!E5) -> 10142.323 | I9: =I7*(1-Inputs!F5) -> 10160.363
A10: Gross profit | B10: 26316 | C10: 29252 | D10: 32255 | E10: =E7-E9 -> 34185.066 | F10: =F7-F9 -> 36068.918 | G10: =G7-G9 -> 37796.752 | H10: =H7-H9 -> 39332.425 | I10: =I7-I9 -> 40641.452
A11: Gross margin | B11: =B10/B7 -> 0.75497031 | C11: =C10/C7 -> 0.77192242 | D11: =D10/D7 -> 0.77676099 | E11: =E10/E7 -> 0.78 | F11: =F10/F7 -> 0.785 | G11: =G10/G7 -> 0.79 | H11: =H10/H7 -> 0.795 | I11: =I10/I7 -> 0.8
A12: Research and development | B12: 4906 | C12: 5493 | D12: 5993 | E12: =E7*Inputs!B6 -> 6223.435 | F12: =F7*Inputs!C6 -> 6478.6209 | G12: =G7*Inputs!D6 -> 6698.1585 | H12: =H7*Inputs!E6 -> 6876.9901 | I12: =I7*Inputs!F6 -> 7010.6505
A13: Sales and marketing | B13: 12877 | C13: 13257 | D13: 14345 | E13: =E7*Inputs!B7 -> 14682.047 | F13: =F7*Inputs!C7 -> 15070.834 | G13: =G7*Inputs!D7 -> 15405.765 | H13: =H7*Inputs!E7 -> 15634.021 | I13: =I7*Inputs!F7 -> 15748.563
A14: General and administrative | B14: 2534 | C14: 2836 | D14: 3000 | E14: =E7*Inputs!B8 -> 3111.7175 | F14: =F7*Inputs!C8 -> 3216.3366 | G14: =G7*Inputs!D8 -> 3301.2353 | H14: =H7*Inputs!E8 -> 3364.2829 | I14: =I7*Inputs!F8 -> 3403.7216
A15: Restructuring | B15: 988 | C15: 461 | D15: 586 | E15: =E7*Inputs!B9 -> 438.27007 | F15: =F7*Inputs!C9 -> 275.68599 | G15: =G7*Inputs!D9 -> 191.37596 | H15: =H7*Inputs!E9 -> 148.42425 | I15: =I7*Inputs!F9 -> 101.60363
A16: Total operating expenses | B16: 21305 | C16: 22047 | D16: 23924 | E16: =SUM(E12:E15) -> 24455.47 | F16: =SUM(F12:F15) -> 25041.478 | G16: =SUM(G12:G15) -> 25596.534 | H16: =SUM(H12:H15) -> 26023.718 | I16: =SUM(I12:I15) -> 26264.538
A17: Income from operations | B17: 5011 | C17: 7205 | D17: 8331 | E17: =E10-E16 -> 9729.5956 | F17: =F10-F16 -> 11027.44 | G17: =G10-G16 -> 12200.217 | H17: =H10-H16 -> 13308.707 | I17: =I10-I16 -> 14376.914
A18: Operating margin | B18: =B17/B7 -> 0.14375879 | C18: =C17/C7 -> 0.19013062 | D18: =D17/D7 -> 0.20062613 | E18: =E17/E7 -> 0.222 | F18: =F17/F7 -> 0.24 | G18: =G17/G7 -> 0.255 | H18: =H17/H7 -> 0.269 | I18: =I17/I7 -> 0.283
A19: Tax expense / (benefit) | B19: -814 | C19: -1241 | D19: -2063 | E19: =-E17*Inputs!B10 -> -2189.159 | F19: =-F17*Inputs!C10 -> -2481.1739 | G19: =-G17*Inputs!D10 -> -2745.0489 | H19: =-H17*Inputs!E10 -> -2994.4592 | I19: =-I17*Inputs!F10 -> -3234.8056
A20: Net income | B20: 4136 | C20: 6197 | D20: 7457 | E20: =E17+E19 -> 7540.4366 | F20: =F17+F19 -> 8546.2658 | G20: =G17+G19 -> 9455.1684 | H20: =H17+H19 -> 10314.248 | I20: =I17+I19 -> 11142.108
A21: Cash Flow / FCF
A22: Depreciation and amortization | B22: 3959 | C22: 3477 | D22: 3631 | E22: =E7*Inputs!B11 -> 3725.2956 | F22: =F7*Inputs!C11 -> 3767.7086 | G22: =G7*Inputs!D11 -> 3827.5191 | H22: =H7*Inputs!E11 -> 3859.0304 | I22: =I7*Inputs!F11 -> 3860.938
A23: Stock-based compensation | B23: 2787 | C23: 3183 | D23: 3509 | E23: =E7*Inputs!B12 -> 3506.1606 | F23: =F7*Inputs!C12 -> 3492.0226 | G23: =G7*Inputs!D12 -> 3444.7672 | H23: =H7*Inputs!E12 -> 3364.2829 | I23: =I7*Inputs!F12 -> 3251.3162
A24: Change in net working capital | B24: -2050 | C24: -1981 | D24: -781 | E24: =E7*Inputs!B14 -> -438.27007 | F24: =F7*Inputs!C14 -> -367.58133 | G24: =G7*Inputs!D14 -> -287.06394 | H24: =H7*Inputs!E14 -> -197.899 | I24: =I7*Inputs!F14 -> -152.40545
A25: Cash flow from operations | B25: 10234 | C25: 13092 | D25: 14996 | E25: =E20+E22+E23+E24 -> 14333.623 | F25: =F20+F22+F23+F24 -> 15438.416 | G25: =G20+G22+G23+G24 -> 16440.391 | H25: =H20+H22+H23+H24 -> 17339.663 | I25: =I20+I22+I23+I24 -> 18101.957
A26: Capital expenditures | B26: -736 | C26: -658 | D26: -594 | E26: =-E7*Inputs!B13 -> -657.40511 | F26: =-F7*Inputs!C13 -> -689.21499 | G26: =-G7*Inputs!D13 -> -717.65984 | H26: =-H7*Inputs!E13 -> -742.12123 | I26: =-I7*Inputs!F13 -> -762.02723
A27: Free cash flow | B27: 9498 | C27: 12434 | D27: 14402 | E27: =E25+E26 -> 13676.218 | F27: =F25+F26 -> 14749.201 | G27: =G25+G26 -> 15722.731 | H27: =H25+H26 -> 16597.541 | I27: =I25+I26 -> 17339.93
A28: Balance Sheet Summary
A29: Cash and cash equivalents | B29: 8472 | C29: 8848 | D29: 7327 | E29: =D29+E27 -> 21003.218 | F29: =E29+F27 -> 35752.418 | G29: =F29+G27 -> 51475.149 | H29: =G29+H27 -> 68072.691 | I29: =H29+I27 -> 85412.62
A30: Marketable securities | B30: 5722 | C30: 5184 | D30: 2238 | E30: =D30 -> 2238 | F30: =E30 -> 2238 | G30: =F30 -> 2238 | H30: =G30 -> 2238 | I30: =H30 -> 2238
A31: Accounts receivable, net | B31: 11414 | C31: 11945 | D31: 14339 | E31: =E7*32% -> 14024.642 | F31: =F7*31.5% -> 14473.515 | G31: =G7*31% -> 14831.637 | H31: =H7*30.5% -> 15089.798 | I31: =I7*30% -> 15240.545
A32: Unearned revenue | B32: 19003 | C32: 20743 | D32: 24317 | E32: =E7*58% -> 25419.664 | F32: =F7*58.5% -> 26879.384 | G32: =G7*59% -> 28227.954 | H32: =H7*59.5% -> 29437.476 | I32: =I7*60% -> 30481.089
A33: Debt | B33: 9426 | C33: 8433 | D33: 14439 | E33: =D33 -> 14439 | F33: =E33 -> 14439 | G33: =F33 -> 14439 | H33: =G33 -> 14439 | I33: =H33 -> 14439
A34: Total stockholders' equity | B34: 59646 | C34: 61173 | D34: 59142 | E34: =D34+E20 -> 66682.437 | F34: =E34+F20 -> 75228.702 | G34: =F34+G20 -> 84683.871 | H34: =G34+H20 -> 94998.119 | I34: =H34+I20 -> 106140.23
A35: Forecast balancing item / other net assets | B35: 0 | C35: 0 | D35: 0 | E35: =E32+E33+E34-E29-E30-E31 -> 69275.241 | F35: =F32+F33+F34-F29-F30-F31 -> 64083.154 | G35: =G32+G33+G34-G29-G30-G31 -> 58806.039 | H35: =H32+H33+H34-H29-H30-H31 -> 53474.106 | I35: =I32+I33+I34-I29-I30-I31 -> 48169.152
A36: Balance check | B36: 0 | C36: 0 | D36: 0 | E36: =E29+E30+E31+E35-E32-E33-E34 -> 0 | F36: =F29+F30+F31+F35-F32-F33-F34 -> 0 | G36: =G29+G30+G31+G35-G32-G33-G34 -> 0 | H36: =H29+H30+H31+H35-H32-H33-H34 -> 0 | I36: =I29+I30+I31+I35-I32-I33-I34 -> 0

Sheet DCF
A1: Discounted Cash Flow — Salesforce, Inc.
A3: Line Item | B3: FY2027E | C3: FY2028E | D3: FY2029E | E3: FY2030E | F3: FY2031E
A4: Unlevered FCF | B4: ='Operating Model'!E27 -> 13676.218 | C4: ='Operating Model'!F27 -> 14749.201 | D4: ='Operating Model'!G27 -> 15722.731 | E4: ='Operating Model'!H27 -> 16597.541 | F4: ='Operating Model'!I27 -> 17339.93
A5: Discount period | B5: 0.5 | C5: 1.5 | D5: 2.5 | E5: 3.5 | F5: 4.5
A6: WACC | B6: =Inputs!B15 -> 0.085 | C6: =Inputs!B15 -> 0.085 | D6: =Inputs!B15 -> 0.085 | E6: =Inputs!B15 -> 0.085 | F6: =Inputs!B15 -> 0.085
A7: PV factor | B7: =1/(1+B6)^B5 -> 0.96003072 | C7: =1/(1+C6)^C5 -> 0.88482094 | D7: =1/(1+D6)^D5 -> 0.81550317 | E7: =1/(1+E6)^E5 -> 0.75161583 | F7: =1/(1+F6)^F5 -> 0.69273348
A8: PV of FCF | B8: =B4*B7 -> 13129.589 | C8: =C4*C7 -> 13050.402 | D8: =D4*D7 -> 12821.937 | E8: =E4*E7 -> 12474.975 | F8: =F4*F7 -> 12011.95
A9: Terminal value | F9: =F4*(1+Inputs!B16)/(Inputs!B15-Inputs!B16) -> 324729.59
A10: PV of terminal value | F10: =F9*F7 -> 224951.06
A11: Enterprise value | F11: =SUM(B8:F8)+F10 -> 288439.91
A12: Less: debt | F12: ='Operating Model'!D32 -> 24317
A13: Add: cash + marketable securities | F13: ='Operating Model'!D28+'Operating Model'!D29 -> 7327
A14: Equity value | F14: =F11-F12+F13 -> 271449.91
A15: Diluted shares | F15: =Inputs!B17 -> 930
A16: Implied share price | F16: =F14/F15 -> 291.88163
A17: Current share price | F17: =Inputs!B18 -> 170
A18: Implied upside / downside | F18: =F16/F17-1 -> 0.71695074
A21: Share Price Sensitivity — WACC vs Terminal Growth
B22: 0.02 | C22: 0.025 | D22: 0.03 | E22: 0.035 | F22: 0.04
A23: 0.075 | B23: =(SUM($B$8:$F$8)+('Operating Model'!$I$27*(1+B$22)/($A23-B$22))/(1+$A23)^4.5-'Operating Model'!$D$32+'Operating Model'!$D$28+'Operating Model'!$D$29)/Inputs!$B$17 -> 299.72477 | C23: =(SUM($B$8:$F$8)+('Operating Model'!$I$27*(1+C$22)/($A23-C$22))/(1+$A23)^4.5-'Operating Model'!$D$32+'Operating Model'!$D$28+'Operating Model'!$D$29)/Inputs!$B$17 -> 326.04394 | D23: =(SUM($B$8:$F$8)+('Operating Model'!$I$27*(1+D$22)/($A23-D$22))/(1+$A23)^4.5-'Operating Model'!$D$32+'Operating Model'!$D$28+'Operating Model'!$D$29)/Inputs!$B$17 -> 358.2118 | E23: =(SUM($B$8:$F$8)+('Operating Model'!$I$27*(1+E$22)/($A23-E$22))/(1+$A23)^4.5-'Operating Model'!$D$32+'Operating Model'!$D$28+'Operating Model'!$D$29)/Inputs!$B$17 -> 398.42163 | F23: =(SUM($B$8:$F$8)+('Operating Model'!$I$27*(1+F$22)/($A23-F$22))/(1+$A23)^4.5-'Operating Model'!$D$32+'Operating Model'!$D$28+'Operating Model'!$D$29)/Inputs!$B$17 -> 450.11999
A24: 0.08 | B24: =(SUM($B$8:$F$8)+('Operating Model'!$I$27*(1+B$22)/($A24-B$22))/(1+$A24)^4.5-'Operating Model'!$D$32+'Operating Model'!$D$28+'Operating Model'!$D$29)/Inputs!$B$17 -> 274.18369 | C24: =(SUM($B$8:$F$8)+('Operating Model'!$I$27*(1+C$22)/($A24-C$22))/(1+$A24)^4.5-'Operating Model'!$D$32+'Operating Model'!$D$28+'Operating Model'!$D$29)/Inputs!$B$17 -> 295.76299 | D24: =(SUM($B$8:$F$8)+('Operating Model'!$I$27*(1+D$22)/($A24-D$22))/(1+$A24)^4.5-'Operating Model'!$D$32+'Operating Model'!$D$28+'Operating Model'!$D$29)/Inputs!$B$17 -> 321.65814 | E24: =(SUM($B$8:$F$8)+('Operating Model'!$I$27*(1+E$22)/($A24-E$22))/(1+$A24)^4.5-'Operating Model'!$D$32+'Operating Model'!$D$28+'Operating Model'!$D$29)/Inputs!$B$17 -> 353.30778 | F24: =(SUM($B$8:$F$8)+('Operating Model'!$I$27*(1+F$22)/($A24-F$22))/(1+$A24)^4.5-'Operating Model'!$D$32+'Operating Model'!$D$28+'Operating Model'!$D$29)/Inputs!$B$17 -> 392.86982
A25: 0.085 | B25: =(SUM($B$8:$F$8)+('Operating Model'!$I$27*(1+B$22)/($A25-B$22))/(1+$A25)^4.5-'Operating Model'!$D$32+'Operating Model'!$D$28+'Operating Model'!$D$29)/Inputs!$B$17 -> 252.68179 | C25: =(SUM($B$8:$F$8)+('Operating Model'!$I$27*(1+C$22)/($A25-C$22))/(1+$A25)^4.5-'Operating Model'!$D$32+'Operating Model'!$D$28+'Operating Model'!$D$29)/Inputs!$B$17 -> 270.64838 | D25: =(SUM($B$8:$F$8)+('Operating Model'!$I$27*(1+D$22)/($A25-D$22))/(1+$A25)^4.5-'Operating Model'!$D$32+'Operating Model'!$D$28+'Operating Model'!$D$29)/Inputs!$B$17 -> 291.88163 | E25: =(SUM($B$8:$F$8)+('Operating Model'!$I$27*(1+E$22)/($A25-E$22))/(1+$A25)^4.5-'Operating Model'!$D$32+'Operating Model'!$D$28+'Operating Model'!$D$29)/Inputs!$B$17 -> 317.36152 | F25: =(SUM($B$8:$F$8)+('Operating Model'!$I$27*(1+F$22)/($A25-F$22))/(1+$A25)^4.5-'Operating Model'!$D$32+'Operating Model'!$D$28+'Operating Model'!$D$29)/Inputs!$B$17 -> 348.50361
A26: 0.09 | B26: =(SUM($B$8:$F$8)+('Operating Model'!$I$27*(1+B$22)/($A26-B$22))/(1+$A26)^4.5-'Operating Model'!$D$32+'Operating Model'!$D$28+'Operating Model'!$D$29)/Inputs!$B$17 -> 234.35052 | C26: =(SUM($B$8:$F$8)+('Operating Model'!$I$27*(1+C$22)/($A26-C$22))/(1+$A26)^4.5-'Operating Model'!$D$32+'Operating Model'!$D$28+'Operating Model'!$D$29)/Inputs!$B$17 -> 249.50462 | D26: =(SUM($B$8:$F$8)+('Operating Model'!$I$27*(1+D$22)/($A26-D$22))/(1+$A26)^4.5-'Operating Model'!$D$32+'Operating Model'!$D$28+'Operating Model'!$D$29)/Inputs!$B$17 -> 267.18441 | E26: =(SUM($B$8:$F$8)+('Operating Model'!$I$27*(1+E$22)/($A26-E$22))/(1+$A26)^4.5-'Operating Model'!$D$32+'Operating Model'!$D$28+'Operating Model'!$D$29)/Inputs!$B$17 -> 288.0787 | F26: =(SUM($B$8:$F$8)+('Operating Model'!$I$27*(1+F$22)/($A26-F$22))/(1+$A26)^4.5-'Operating Model'!$D$32+'Operating Model'!$D$28+'Operating Model'!$D$29)/Inputs!$B$17 -> 313.15186
A27: 0.095 | B27: =(SUM($B$8:$F$8)+('Operating Model'!$I$27*(1+B$22)/($A27-B$22))/(1+$A27)^4.5-'Operating Model'!$D$32+'Operating Model'!$D$28+'Operating Model'!$D$29)/Inputs!$B$17 -> 218.55303 | C27: =(SUM($B$8:$F$8)+('Operating Model'!$I$27*(1+C$22)/($A27-C$22))/(1+$A27)^4.5-'Operating Model'!$D$32+'Operating Model'!$D$28+'Operating Model'!$D$29)/Inputs!$B$17 -> 231.47789 | D27: =(SUM($B$8:$F$8)+('Operating Model'!$I$27*(1+D$22)/($A27-D$22))/(1+$A27)^4.5-'Operating Model'!$D$32+'Operating Model'!$D$28+'Operating Model'!$D$29)/Inputs!$B$17 -> 246.39118 | E27: =(SUM($B$8:$F$8)+('Operating Model'!$I$27*(1+E$22)/($A27-E$22))/(1+$A27)^4.5-'Operating Model'!$D$32+'Operating Model'!$D$28+'Operating Model'!$D$29)/Inputs!$B$17 -> 263.79002 | F27: =(SUM($B$8:$F$8)+('Operating Model'!$I$27*(1+F$22)/($A27-F$22))/(1+$A27)^4.5-'Operating Model'!$D$32+'Operating Model'!$D$28+'Operating Model'!$D$29)/Inputs!$B$17 -> 284.35229

Sheet QA Checks
A1: QA Checks — Salesforce Model
A3: Check | B3: FY2024A | C3: FY2025A | D3: FY2026A | E3: Status
A4: Revenue ties to filing | B4: ='Historical Actuals'!B7-'Operating Model'!B7 -> 0 | C4: ='Historical Actuals'!C7-'Operating Model'!C7 -> 0 | D4: ='Historical Actuals'!D7-'Operating Model'!D7 -> 0 | E4: =IF(AND(ABS(B4)<0.1,ABS(C4)<0.1,ABS(D4)<0.1),"PASS","FAIL") -> PASS
A5: Operating income ties to filing | B5: ='Historical Actuals'!B17-'Operating Model'!B17 -> 0 | C5: ='Historical Actuals'!C17-'Operating Model'!C17 -> 0 | D5: ='Historical Actuals'!D17-'Operating Model'!D17 -> 0 | E5: =IF(AND(ABS(B5)<0.1,ABS(C5)<0.1,ABS(D5)<0.1),"PASS","FAIL") -> PASS
A6: Net income ties to filing | B6: ='Historical Actuals'!B22-'Operating Model'!B20 -> 0 | C6: ='Historical Actuals'!C22-'Operating Model'!C20 -> 0 | D6: ='Historical Actuals'!D22-'Operating Model'!D20 -> 0 | E6: =IF(AND(ABS(B6)<0.1,ABS(C6)<0.1,ABS(D6)<0.1),"PASS","FAIL") -> PASS
A7: Cash ties to balance sheet | B7: ='Historical Actuals'!B25-'Operating Model'!B29 -> 0 | C7: ='Historical Actuals'!C25-'Operating Model'!C29 -> 0 | D7: ='Historical Actuals'!D25-'Operating Model'!D29 -> 0 | E7: =IF(AND(ABS(B7)<0.1,ABS(C7)<0.1,ABS(D7)<0.1),"PASS","FAIL") -> PASS
A8: Debt ties to balance sheet | B8: =('Historical Actuals'!B42+'Historical Actuals'!B44)-'Operating Model'!B33 -> 0 | C8: =('Historical Actuals'!C42+'Historical Actuals'!C44)-'Operating Model'!C33 -> 0 | D8: =('Historical Actuals'!D42+'Historical Actuals'!D44)-'Operating Model'!D33 -> 0 | E8: =IF(AND(ABS(B8)<0.1,ABS(C8)<0.1,ABS(D8)<0.1),"PASS","FAIL") -> PASS
A9: Cash flow ending cash ties | B9: ='Historical Actuals'!B69-'Operating Model'!B29 -> 0 | C9: ='Historical Actuals'!C69-'Operating Model'!C29 -> 0 | D9: ='Historical Actuals'!D69-'Operating Model'!D29 -> 0 | E9: =IF(AND(ABS(B9)<0.1,ABS(C9)<0.1,ABS(D9)<0.1),"PASS","FAIL") -> PASS
A10: Historical balance check | B10: ='Historical Actuals'!B38-'Historical Actuals'!B49 -> 0 | C10: ='Historical Actuals'!C38-'Historical Actuals'!C49 -> 0 | D10: ='Historical Actuals'!D38-'Historical Actuals'!D49 -> 0 | E10: =IF(AND(ABS(B10)<0.1,ABS(C10)<0.1,ABS(D10)<0.1),"PASS","FAIL") -> PASS
A11: Forecast balance check | E11: =IF(AND(ABS('Operating Model'!E36)<1,ABS('Operating Model'!F36)<1,ABS('Operating Model'!G36)<1,ABS('Operating Model'!H36)<1,ABS('Operating Model'!I36)<1),"PASS","FAIL") -> PASS

Sheet Sources
A1: Source ID | B1: Document | C1: URL | D1: Relevant Lines / Usage
A2: CRM FY2026 10-K | B2: Salesforce FY2026 Form 10-K (period ended Jan. 31, 2026) | C2: https://www.sec.gov/Archives/edgar/data/1108524/000110852426000060/crm-20260131.htm | D2: FY2026/FY2025 balance sheet; FY2026/FY2025/FY2024 income statement and cash flow; revenue mix; SBC/amortization
A3: CRM FY2025 10-K | B3: Salesforce FY2025 Form 10-K (period ended Jan. 31, 2025) | C3: https://www.sec.gov/Archives/edgar/data/1108524/000110852425000006/crm-20250131.htm | D3: FY2024 balance sheet; FY2025/FY2024/FY2023 comparison support
A4: SEC Filing Index | B4: EDGAR Filing Documents for 0001108524-26-000060 | C4: https://www.sec.gov/Archives/edgar/data/1108524/0001108524-26-000060-index.htm | D4: Confirms 10-K accession and filing details
